Workbook

Sheet WSO Cover Page
B2: Rightmove plc
B3: Leveraged Buyout Analysis
B6: Company Overview
B7: Ticker: RMV LN (London Stock Exchange)
B8: Sector: RE Online Platform
B9: Description: UK's largest online real estate portal, listing residential and commercial property for sale and rent. Operates rightmove.co.uk.
B11: Key Statistics (FY2025A)
B12: Revenue (£m) | C12: ='Income Statement'!G6 -> 425.129
B13: EBITDA (£m) | C13: ='Income Statement'!G25 -> 296.202
B14: EBITDA Margin | C14: ='Income Statement'!G26 -> 0.6967344
B15: Net Income (£m) | C15: ='Income Statement'!G43 -> 217.084
B16: FCF Conversion (EBITDA-Capex / EBITDA) | C16: ='Income Statement'!G48 -> 0.9969514
B18: LBO Transaction Summary
B19: Entry Multiple (EV/LTM EBITDA) | C19: ='LBO Modelling'!C6 -> 12.5
B20: Enterprise Value (£m) | C20: ='LBO Modelling'!D11 -> 3702.525
B21: Total Debt (£m) | C21: ='LBO Modelling'!D8 -> 2369.616
B22: Sponsor Equity (£m) | C22: ='LBO Modelling'!D12 -> 1504.3341
B23: Leverage (Debt / LTM EBITDA) | C23: ='LBO Modelling'!C7 -> 8
B25: Returns (5-Year Hold, Exit 2030)
B26: IRR | C26: ='PE Returns analysis'!C22 -> 0.25036765
B27: MOIC | C27: ='PE Returns analysis'!C23 -> 3.0562483

Sheet DCF
A1: Rightmove plc
A2: Discounted Cash Flow Valuation
A4: (YE 31-Dec, £m)
D5: 1 | E5: 2 | F5: 3 | G5: 4 | H5: 5 | I5: 6 | J5: 7 | K5: 8 | L5: 9 | M5: 10
C6: ='Income Statement'!G4 -> 2025 | D6: ='Income Statement'!H4 -> 2026 | E6: ='Income Statement'!I4 -> 2027 | F6: ='Income Statement'!J4 -> 2028 | G6: ='Income Statement'!K4 -> 2029 | H6: ='Income Statement'!L4 -> 2030 | I6: ='Income Statement'!M4 -> 2031 | J6: ='Income Statement'!N4 -> 2032 | ... M6: ='Income Statement'!Q4 -> 2035
A8: EBITDA | C8: ='Income Statement'!G25 -> 296.202 | D8: ='Income Statement'!H25 -> 325.89255 | E8: ='Income Statement'!I25 -> 355.78145 | F8: ='Income Statement'!J25 -> 387.05034 | G8: ='Income Statement'!K25 -> 416.08023 | H8: ='Income Statement'!L25 -> 442.58544 | I8: ='Income Statement'!M25 -> 465.15244 | J8: ='Income Statement'!N25 -> 484.33349 | ... M8: ='Income Statement'!Q25 -> 534.49339
A10: (-) D&A | D10: =-'Income Statement'!H28 -> 4.6225893 | E10: =-'Income Statement'!I28 -> 5.0110063 | F10: =-'Income Statement'!J28 -> 5.4132915 | G10: =-'Income Statement'!K28 -> 5.7949893 | H10: =-'Income Statement'!L28 -> 6.14702 | I10: =-'Income Statement'!M28 -> 6.4604506 | J10: =-'Income Statement'!N28 -> 6.7268541 | K10: =-'Income Statement'!O28 -> 6.9741779 | ... M10: =-'Income Statement'!Q28 -> 7.4235193
A12: EBIT | D12: =+D8-D10 -> 321.26996 | E12: =+E8-E10 -> 350.77044 | F12: =+F8-F10 -> 381.63705 | G12: =+G8-G10 -> 410.28524 | H12: =+H8-H10 -> 436.43842 | I12: =+I8-I10 -> 458.69199 | J12: =+J8-J10 -> 477.60664 | K12: =+K8-K10 -> 495.16663 | ... M12: =+M8-M10 -> 527.06987
A14: (-) Taxes on EBIT (unlevered) | D14: =-D12*Assumptions!$D$83 -> -80.317489 | E14: =-E12*Assumptions!$D$83 -> -87.692611 | F14: =-F12*Assumptions!$D$83 -> -95.409262 | G14: =-G12*Assumptions!$D$83 -> -102.57131 | H14: =-H12*Assumptions!$D$83 -> -109.10961 | I14: =-I12*Assumptions!$D$83 -> -114.673 | J14: =-J12*Assumptions!$D$83 -> -119.40166 | K14: =-K12*Assumptions!$D$83 -> -123.79166 | ... M14: =-M12*Assumptions!$D$83 -> -131.76747
A16: (-) Capex | D16: =+'Income Statement'!H34 -> -4.1603304 | E16: =+'Income Statement'!I34 -> -4.5099057 | F16: =+'Income Statement'!J34 -> -4.8719623 | G16: =+'Income Statement'!K34 -> -5.2154903 | H16: =+'Income Statement'!L34 -> -5.532318 | I16: =+'Income Statement'!M34 -> -5.8144056 | J16: =+'Income Statement'!N34 -> -6.0541687 | K16: =+'Income Statement'!O34 -> -6.2767601 | ... M16: =+'Income Statement'!Q34 -> -6.6811674
A18: (-) Δ NWC | D18: =+'Cash Flow Statement'!H10 -> -0.12048428 | E18: =+'Cash Flow Statement'!I10 -> 0.34291346 | F18: =+'Cash Flow Statement'!J10 -> 0.35087154 | G18: =+'Cash Flow Statement'!K10 -> 0.34166586 | H18: =+'Cash Flow Statement'!L10 -> 0.31878644 | I18: =+'Cash Flow Statement'!M10 -> 0.29796728 | J18: =+'Cash Flow Statement'!N10 -> 0.25326029 | K18: =+'Cash Flow Statement'!O10 -> 0.23512193 | ... M18: =+'Cash Flow Statement'!Q10 -> 0.20555171
A20: Unlevered FCF | D20: =+D12+D14+D16+D18+D10 -> 241.29424 | E20: =+E12+E14+E16+E18+E10 -> 263.92185 | F20: =+F12+F14+F16+F18+F10 -> 287.11999 | G20: =+G12+G14+G16+G18+G10 -> 308.63509 | H20: =+H12+H14+H16+H18+H10 -> 328.26231 | I20: =+I12+I14+I16+I18+I10 -> 344.96301 | J20: =+J12+J14+J16+J18+J10 -> 359.13093 | K20: =+K12+K14+K16+K18+K10 -> 372.30751 | ... M20: =+M12+M14+M16+M18+M10 -> 396.25031
A22: Discount Factor | D22: =1/((1+$C$26)^D5) -> 0.9224922 | E22: =1/((1+$C$26)^E5) -> 0.85099187 | F22: =1/((1+$C$26)^F5) -> 0.78503336 | G22: =1/((1+$C$26)^G5) -> 0.72418716 | H22: =1/((1+$C$26)^H5) -> 0.66805701 | I22: =1/((1+$C$26)^I5) -> 0.61627738 | J22: =1/((1+$C$26)^J5) -> 0.56851108 | K22: =1/((1+$C$26)^K5) -> 0.52444704 | ... M22: =1/((1+$C$26)^M5) -> 0.44630017
A24: Discounted FCF | D24: =+D20*D22 -> 222.59206 | E24: =+E20*E22 -> 224.59535 | F24: =+F20*F22 -> 225.39877 | G24: =+G20*G22 -> 223.50957 | H24: =+H20*H22 -> 219.29793 | I24: =+I20*I22 -> 212.5929 | J24: =+J20*J22 -> 204.16991 | K24: =+K20*K22 -> 195.25557 | ... M24: =+M20*M22 -> 176.84658
A26: WACC | C26: ='WACC Calculation'!C19 -> 0.08402
A27: Perpetuity Growth Rate | C27: 0.025
A30: Terminal Value | C30: =(M20*(1+C27))/(C26-C27) -> 6881.6768
A31: Discounted Terminal Value | C31: =C30*M22 -> 3071.2935
A33: PV of Explicit Cash Flows | C33: =SUM(D24:M24) -> 2090.3909
A35: Enterprise Value | C35: =+C31+C33 -> 5161.6844
A36: Less: Net Debt (current) | C36: ='Balance Sheet'!G63 -> -35.722
A37: Less: Minority Interest | C37: 0
A38: Equity Value (Standalone) | C38: =+C35-C36-C37 -> 5197.4064
A40: Implied EV / FY+1 EBITDA | C40: =+C35/D8 -> 15.838608
A41: Implied EV / FY+1 EBIT | C41: =+C35/D12 -> 16.066502

Sheet Assumptions
B2: Select Case | C2: 1
B3: Base Case | C3: 1
B4: Downside case | C4: 2
B5: Upside case | C5: 3
B8: 1. TRANSACTION STRUCTURE & DEAL + DEBT ASSUMPTIONS
B9: Entry Multiple | C9: 12.5
B10: Exit Multiple | C10: 12.5
B11: Leverage (Total Debt / LTM EBITDA) | C11: 8
B12: Senior Debt | C12: 5.5 | D12: > | E12: at rate | F12: 0.065
B13: Subordinated Debt | C13: =C11-C12 -> 2.5 | D13: > | E13: at rate | F13: 0.095
B14: Senior Amortisation % | C14: 0.05
B15: Cash Sweep % | C15: 0.5
B16: Revolver Capacity (£m) | C16: 200
B17: Revolver Interest Rate | C17: 0.075
B18: Revolver Commitment Fee | C18: 0.005
B20: 2. Transaction Cost and Acquisition Price Rationale
B21: Transaction Fees (% of EV) | C21: 0.025
B22: Financing Fees (% of debt) | C22: 0.02
B23: Min Cash Balance (£m) | C23: 20
B25: Share Price | C25: 402 | D25: Closing Value May 15th
B26: Shares Outstanding | C26: 752.1
B27: Control Premium | C27: =C29/C28-1 -> 0.22460593
B28: Equity Value | C28: =C25*C26/100 -> 3023.442
B29: Purchase Value | C29: ='LBO Modelling'!G17 -> 3702.525
B31: 3. OPERATING MODEL ASSUMPTIONS
B33: Agency Revenue Growth
B34: =$C$2 -> 1 | D34: 2021 | E34: =+D34+1 -> 2022 | F34: =+E34+1 -> 2023 | G34: =+F34+1 -> 2024 | H34: =+G34+1 -> 2025 | I34: =+H34+1 -> 2026 | J34: =+I34+1 -> 2027 | K34: =+J34+1 -> 2028 | L34: =+K34+1 -> 2029 | ... R34: =+Q34+1 -> 2035
B35: Actual | I35: =CHOOSE($B34,I36,I37,I38) -> 0.07 | J35: =CHOOSE($B34,J36,J37,J38) -> 0.07 | K35: =CHOOSE($B34,K36,K37,K38) -> 0.07 | L35: =CHOOSE($B34,L36,L37,L38) -> 0.06 | M35: =CHOOSE($B34,M36,M37,M38) -> 0.05 | N35: =CHOOSE($B34,N36,N37,N38) -> 0.04 | O35: =CHOOSE($B34,O36,O37,O38) -> 0.03 | P35: =CHOOSE($B34,P36,P37,P38) -> 0.03 | ... R35: =CHOOSE($B34,R36,R37,R38) -> 0.03
B36: Base | I36: 0.07 | J36: 0.07 | K36: 0.07 | L36: 0.06 | M36: 0.05 | N36: 0.04 | O36: 0.03 | P36: 0.03 | Q36: 0.03 | R36: 0.03
B37: Downside | I37: 0.04 | J37: 0.04 | K37: 0.04 | L37: 0.03 | M37: 0.02 | N37: 0.01 | O37: 0 | P37: 0 | Q37: 0 | R37: 0
B38: Upside | I38: 0.09 | J38: 0.09 | K38: 0.09 | L38: 0.08 | M38: 0.07 | N38: 0.06 | O38: 0.05 | P38: 0.05 | Q38: 0.05 | R38: 0.05
B41: New Homes Revenue Growth
B42: =$C$2 -> 1 | D42: 2021 | E42: =+D42+1 -> 2022 | F42: =+E42+1 -> 2023 | G42: =+F42+1 -> 2024 | H42: =+G42+1 -> 2025 | I42: =+H42+1 -> 2026 | J42: =+I42+1 -> 2027 | K42: =+J42+1 -> 2028 | L42: =+K42+1 -> 2029 | ... R42: =+Q42+1 -> 2035
B43: Actual | I43: =CHOOSE($B42,I44,I45,I46) -> 0.12 | J43: =CHOOSE($B42,J44,J45,J46) -> 0.11 | K43: =CHOOSE($B42,K44,K45,K46) -> 0.1 | L43: =CHOOSE($B42,L44,L45,L46) -> 0.09 | M43: =CHOOSE($B42,M44,M45,M46) -> 0.08 | N43: =CHOOSE($B42,N44,N45,N46) -> 0.07 | O43: =CHOOSE($B42,O44,O45,O46) -> 0.06 | P43: =CHOOSE($B42,P44,P45,P46) -> 0.05 | ... R43: =CHOOSE($B42,R44,R45,R46) -> 0.03
B44: Base | I44: 0.12 | J44: 0.11 | K44: 0.1 | L44: 0.09 | M44: 0.08 | N44: 0.07 | O44: 0.06 | P44: 0.05 | Q44: 0.04 | R44: 0.03
B45: Downside | I45: 0.08 | J45: 0.07 | K45: 0.06 | L45: 0.05 | M45: 0.04 | N45: 0.03 | O45: 0.02 | P45: 0.01 | Q45: 0 | R45: 0
B46: Upside | I46: 0.15 | J46: 0.14 | K46: 0.13 | L46: 0.12 | M46: 0.11 | N46: 0.1 | O46: 0.09 | P46: 0.08 | Q46: 0.07 | R46: 0.06
B49: Other Revenue Growth
B50: =$C$2 -> 1 | D50: 2021 | E50: =+D50+1 -> 2022 | F50: =+E50+1 -> 2023 | G50: =+F50+1 -> 2024 | H50: =+G50+1 -> 2025 | I50: =+H50+1 -> 2026 | J50: =+I50+1 -> 2027 | K50: =+J50+1 -> 2028 | L50: =+K50+1 -> 2029 | ... R50: =+Q50+1 -> 2035
B51: Actual | I51: =CHOOSE($B50,I52,I53,I54) -> 0.15 | J51: =CHOOSE($B50,J52,J53,J54) -> 0.13 | K51: =CHOOSE($B50,K52,K53,K54) -> 0.11 | L51: =CHOOSE($B50,L52,L53,L54) -> 0.1 | M51: =CHOOSE($B50,M52,M53,M54) -> 0.09 | N51: =CHOOSE($B50,N52,N53,N54) -> 0.08 | O51: =CHOOSE($B50,O52,O53,O54) -> 0.07 | P51: =CHOOSE($B50,P52,P53,P54) -> 0.05 | ... R51: =CHOOSE($B50,R52,R53,R54) -> 0.03
...

Sheet Income Statement
B2: Rightmove plc - Income Statement
B4: (YE 31-Dec, £m) | C4: 2021 | D4: =+C4+1 -> 2022 | E4: =+D4+1 -> 2023 | F4: =+E4+1 -> 2024 | G4: =+F4+1 -> 2025 | H4: =+G4+1 -> 2026 | I4: =+H4+1 -> 2027 | J4: =+I4+1 -> 2028 | K4: =+J4+1 -> 2029 | ... Q4: =+P4+1 -> 2035
B6: Total Revenue | C6: =+C9+C13+C17 -> 304.886 | D6: =+D9+D13+D17 -> 332.622 | E6: =+E9+E13+E17 -> 364.316 | F6: =+F9+F13+F17 -> 389.882 | G6: =+G9+G13+G17 -> 425.129 | H6: =+H9+H13+H17 -> 462.25893 | I6: =+I9+I13+I17 -> 501.10063 | J6: =+J9+J13+J17 -> 541.32915 | ... Q6: =+Q9+Q13+Q17 -> 742.35193 | S6: =(H7+I7+J7+K7+L7)/5 -> 0.076580573
B7: % Growth | D7: =+D6/C6-1 -> 0.090971707 | E7: =+E6/D6-1 -> 0.095285339 | F7: =+F6/E6-1 -> 0.070175342 | G7: =+G6/F6-1 -> 0.090404276 | H7: =+H6/G6-1 -> 0.087338032 | I7: =+I6/H6-1 -> 0.08402586 | J7: =+J6/I6-1 -> 0.080280303 | K7: =+K6/J6-1 -> 0.070511226 | ... Q7: =+Q6/P6-1 -> 0.03
B9: Agency Revenue | C9: 218.55056 | D9: 238.43247 | E9: 261.15159 | F9: 279.47799 | G9: 304.744 | H9: =+G9*(1+Assumptions!I35) -> 326.07608 | I9: =+H9*(1+Assumptions!J35) -> 348.90141 | J9: =+I9*(1+Assumptions!K35) -> 373.3245 | K9: =+J9*(1+Assumptions!L35) -> 395.72397 | L9: =+K9*(1+Assumptions!M35) -> 415.51017 | M9: =+L9*(1+Assumptions!N35) -> 432.13058 | N9: =+M9*(1+Assumptions!O35) -> 445.0945 | O9: =+N9*(1+Assumptions!P35) -> 458.44733 | ... Q9: =+P9*(1+Assumptions!R35) -> 486.36677
B10: % of Total Revenue | C10: =+C9/C6 -> 0.71682713 | D10: =+D9/D6 -> 0.71682713 | E10: =+E9/E6 -> 0.71682713 | F10: =+F9/F6 -> 0.71682713 | G10: =+G9/G6 -> 0.71682713 | H10: =+H9/H6 -> 0.70539704 | I10: =+I9/I6 -> 0.69627013 | J10: =+J9/J6 -> 0.6896442 | ... Q10: =+Q9/Q6 -> 0.65517008
B11: % Growth | D11: =+D9/C9-1 -> 0.090971707 | E11: =+E9/D9-1 -> 0.095285339 | F11: =+F9/E9-1 -> 0.070175342 | G11: =+G9/F9-1 -> 0.090404276 | H11: =+H9/G9-1 -> 0.07 | I11: =+I9/H9-1 -> 0.07 | J11: =+J9/I9-1 -> 0.07 | K11: =+K9/J9-1 -> 0.06 | ... Q11: =+Q9/P9-1 -> 0.03
B13: New Homes Revenue | C13: 54.023749 | D13: 58.938382 | E13: 64.554345 | F13: 69.084469 | G13: 75.33 | H13: =+G13*(1+Assumptions!I43) -> 84.3696 | I13: =+H13*(1+Assumptions!J43) -> 93.650256 | J13: =+I13*(1+Assumptions!K43) -> 103.01528 | K13: =+J13*(1+Assumptions!L43) -> 112.28666 | L13: =+K13*(1+Assumptions!M43) -> 121.26959 | M13: =+L13*(1+Assumptions!N43) -> 129.75846 | N13: =+M13*(1+Assumptions!O43) -> 137.54397 | O13: =+N13*(1+Assumptions!P43) -> 144.42117 | ... Q13: =+P13*(1+Assumptions!R43) -> 154.70395
B14: % of Total Revenue | C14: =+C13/C6 -> 0.17719328 | D14: =+D13/D6 -> 0.17719328 | E14: =+E13/E6 -> 0.17719328 | F14: =+F13/F6 -> 0.17719328 | G14: =+G13/G6 -> 0.17719328 | H14: =+H13/H6 -> 0.18251589 | I14: =+I13/I6 -> 0.18688912 | J14: =+J13/J6 -> 0.19030064 | ... Q14: =+Q13/Q6 -> 0.20839705
B15: % Growth | D15: =+D13/C13-1 -> 0.090971707 | E15: =+E13/D13-1 -> 0.095285339 | F15: =+F13/E13-1 -> 0.070175342 | G15: =+G13/F13-1 -> 0.090404276 | H15: =+H13/G13-1 -> 0.12 | I15: =+I13/H13-1 -> 0.11 | J15: =+J13/I13-1 -> 0.1 | K15: =+K13/J13-1 -> 0.09 | ... Q15: =+Q13/P13-1 -> 0.03
B17: Other Revenue | C17: 32.311695 | D17: 35.251145 | E17: 38.610063 | F17: 41.319537 | G17: 45.055 | H17: =+G17*(1+Assumptions!I51) -> 51.81325 | I17: =+H17*(1+Assumptions!J51) -> 58.548972 | J17: =+I17*(1+Assumptions!K51) -> 64.989359 | K17: =+J17*(1+Assumptions!L51) -> 71.488295 | L17: =+K17*(1+Assumptions!M51) -> 77.922242 | M17: =+L17*(1+Assumptions!N51) -> 84.156021 | N17: =+M17*(1+Assumptions!O51) -> 90.046943 | O17: =+N17*(1+Assumptions!P51) -> 94.54929 | ... Q17: =+P17*(1+Assumptions!R51) -> 101.2812
B18: % of Total Revenue | C18: =+C17/C6 -> 0.1059796 | D18: =+D17/D6 -> 0.1059796 | E18: =+E17/E6 -> 0.1059796 | F18: =+F17/F6 -> 0.1059796 | G18: =+G17/G6 -> 0.1059796 | H18: =+H17/H6 -> 0.11208707 | I18: =+I17/I6 -> 0.11684075 | J18: =+J17/J6 -> 0.12005516 | ... Q18: =+Q17/Q6 -> 0.13643286
B19: % Growth | D19: =+D17/C17-1 -> 0.090971707 | E19: =+E17/D17-1 -> 0.095285339 | F19: =+F17/E17-1 -> 0.070175342 | G19: =+G17/F17-1 -> 0.090404276 | H19: =+H17/G17-1 -> 0.15 | I19: =+I17/H17-1 -> 0.13 | J19: =+J17/I17-1 -> 0.11 | K19: =+K17/J17-1 -> 0.1 | ... Q19: =+Q17/P17-1 -> 0.03
B22: Operating Expenses (SG&A) | C22: -76.754 | D22: -86.694 | E22: -101.296 | F22: -127.551 | G22: -128.922 | H22: =-Assumptions!I60*H6 -> -136.36638 | I22: =-Assumptions!J60*I6 -> -145.31918 | J22: =-Assumptions!K60*J6 -> -154.27881 | K22: =-Assumptions!L60*K6 -> -163.4187 | L22: =-Assumptions!M60*L6 -> -172.11656 | M22: =-Assumptions!N60*M6 -> -180.89262 | N22: =-Assumptions!O60*N6 -> -188.35191 | O22: =-Assumptions!P60*O6 -> -195.27698 | ... Q22: =-Assumptions!R60*Q6 -> -207.85854
B23: % of Revenue | C23: =-C22/C6 -> 0.25174655 | D23: =-D22/D6 -> 0.2606382 | E23: =-E22/E6 -> 0.27804434 | F23: =-F22/F6 -> 0.32715283 | G23: =-G22/G6 -> 0.30325384 | H23: =-H22/H6 -> 0.295 | I23: =-I22/I6 -> 0.29 | J23: =-J22/J6 -> 0.285 | ... Q23: =-Q22/Q6 -> 0.28
B25: EBITDA | C25: 230.539 | D25: 245.929 | E25: 263.017 | F25: 262.329 | G25: 296.202 | H25: =+H6+H22 -> 325.89255 | I25: =+I6+I22 -> 355.78145 | J25: =+J6+J22 -> 387.05034 | K25: =+K6+K22 -> 416.08023 | L25: =+L6+L22 -> 442.58544 | M25: =+M6+M22 -> 465.15244 | N25: =+N6+N22 -> 484.33349 | O25: =+O6+O22 -> 502.14081 | ... Q25: =+Q6+Q22 -> 534.49339
B26: % margin | C26: =+C25/C6 -> 0.7561482 | D26: =+D25/D6 -> 0.7393648 | E26: =+E25/E6 -> 0.72194743 | F26: =+F25/F6 -> 0.67284204 | G26: =+G25/G6 -> 0.6967344 | H26: =+H25/H6 -> 0.705 | I26: =+I25/I6 -> 0.71 | J26: =+J25/J6 -> 0.715 | ... Q26: =+Q25/Q6 -> 0.72
B28: Depreciation & Amortisation + Other | C28: -4.439 | D28: -4.586 | E28: -4.984 | F28: -5.999 | G28: -8.328 | H28: =-Assumptions!I68*H6 -> -4.6225893 | I28: =-Assumptions!J68*I6 -> -5.0110063 | J28: =-Assumptions!K68*J6 -> -5.4132915 | K28: =-Assumptions!L68*K6 -> -5.7949893 | L28: =-Assumptions!M68*L6 -> -6.14702 | M28: =-Assumptions!N68*M6 -> -6.4604506 | N28: =-Assumptions!O68*N6 -> -6.7268541 | O28: =-Assumptions!P68*O6 -> -6.9741779 | ... Q28: =-Assumptions!R68*Q6 -> -7.4235193
B29: % of Revenue | C29: =-C28/C6 -> 0.01455954 | D29: =-D28/D6 -> 0.013787422 | E29: =-E28/E6 -> 0.013680431 | F29: =-F28/F6 -> 0.015386707 | G29: =-G28/G6 -> 0.019589348 | H29: =-H28/H6 -> 0.01 | I29: =-I28/I6 -> 0.01 | J29: =-J28/J6 -> 0.01 | ... Q29: =-Q28/Q6 -> 0.01
B31: EBIT | C31: =+C25+C28 -> 226.1 | D31: =+D25+D28 -> 241.343 | E31: =+E25+E28 -> 258.033 | F31: =+F25+F28 -> 256.33 | G31: =+G25+G28 -> 287.874 | H31: =+H25+H28 -> 321.26996 | I31: =+I25+I28 -> 350.77044 | J31: =+J25+J28 -> 381.63705 | ... Q31: =+Q25+Q28 -> 527.06987
B32: % margin | C32: =+C31/C6 -> 0.74158866 | D32: =+D31/D6 -> 0.72557738 | E32: =+E31/E6 -> 0.708267 | F32: =+F31/F6 -> 0.65745533 | G32: =+G31/G6 -> 0.67714505 | H32: =+H31/H6 -> 0.695 | I32: =+I31/I6 -> 0.7 | J32: =+J31/J6 -> 0.705 | ... Q32: =+Q31/Q6 -> 0.71
B34: Capital Expenditure (memo) | C34: -0.7 | D34: -0.835 | E34: -2.018 | F34: -1.055 | G34: -0.903 | H34: =-Assumptions!I77*H6 -> -4.1603304 | I34: =-Assumptions!J77*I6 -> -4.5099057 | J34: =-Assumptions!K77*J6 -> -4.8719623 | K34: =-Assumptions!L77*K6 -> -5.2154903 | L34: =-Assumptions!M77*L6 -> -5.532318 | M34: =-Assumptions!N77*M6 -> -5.8144056 | N34: =-Assumptions!O77*N6 -> -6.0541687 | O34: =-Assumptions!P77*O6 -> -6.2767601 | ... Q34: =-Assumptions!R77*Q6 -> -6.6811674
B35: % of Revenue | C35: =-C34/C6 -> 0.0022959401 | D35: =-D34/D6 -> 0.0025103571 | E35: =-E34/E6 -> 0.0055391473 | F35: =-F34/F6 -> 0.0027059469 | G35: =-G34/G6 -> 0.0021240612 | H35: =-H34/H6 -> 0.009 | I35: =-I34/I6 -> 0.009 | J35: =-J34/J6 -> 0.009 | ... Q35: =-Q34/Q6 -> 0.009
B37: Interest Expense | C37: -0.451 | D37: -0.061 | E37: 1.736 | F37: 2.082 | G37: 2.089 | H37: ='LBO Modelling'!C66 -> 0 | I37: ='LBO Modelling'!D66 -> 0 | J37: ='LBO Modelling'!E66 -> 0 | K37: ='LBO Modelling'!F66 -> 0 | L37: ='LBO Modelling'!G66 -> 0 | M37: ='LBO Modelling'!H66 -> 0 | N37: ='LBO Modelling'!I66 -> 0 | O37: ='LBO Modelling'!J66 -> 0 | ... Q37: ='LBO Modelling'!L66 -> 0
B39: EBT (Pretax Income) | C39: =+C31+C37 -> 225.649 | D39: =+D31+D37 -> 241.282 | E39: =+E31+E37 -> 259.769 | F39: =+F31+F37 -> 258.412 | G39: =+G31+G37 -> 289.963 | H39: =+H31+H37 -> 321.26996 | I39: =+I31+I37 -> 350.77044 | J39: =+J31+J37 -> 381.63705 | ... Q39: =+Q31+Q37 -> 527.06987
B40: Income Taxes | C40: -42.553 | D40: -45.604 | E40: -60.62 | F40: -65.687 | G40: -72.879 | H40: =-MAX(H39,0)*Assumptions!$D$83 -> -80.317489 | I40: =-MAX(I39,0)*Assumptions!$D$83 -> -87.692611 | J40: =-MAX(J39,0)*Assumptions!$D$83 -> -95.409262 | K40: =-MAX(K39,0)*Assumptions!$D$83 -> -102.57131 | L40: =-MAX(L39,0)*Assumptions!$D$83 -> -109.10961 | M40: =-MAX(M39,0)*Assumptions!$D$83 -> -114.673 | N40: =-MAX(N39,0)*Assumptions!$D$83 -> -119.40166 | O40: =-MAX(O39,0)*Assumptions!$D$83 -> -123.79166 | ... Q40: =-MAX(Q39,0)*Assumptions!$D$83 -> -131.76747
B41: Effective tax rate | C41: =IFERROR(-C40/C39,0) -> 0.18858049 | D41: =IFERROR(-D40/D39,0) -> 0.18900705 | E41: =IFERROR(-E40/E39,0) -> 0.23336118 | F41: =IFERROR(-F40/F39,0) -> 0.25419485 | G41: =IFERROR(-G40/G39,0) -> 0.25133896 | H41: =IFERROR(-H40/H39,0) -> 0.25 | I41: =IFERROR(-I40/I39,0) -> 0.25 | J41: =IFERROR(-J40/J39,0) -> 0.25 | ... Q41: =IFERROR(-Q40/Q39,0) -> 0.25
B43: Net Income | C43: =+C39+C40 -> 183.096 | D43: =+D39+D40 -> 195.678 | E43: =+E39+E40 -> 199.149 | F43: =+F39+F40 -> 192.725 | G43: =+G39+G40 -> 217.084 | H43: =+H39+H40 -> 240.95247 | I43: =+I39+I40 -> 263.07783 | J43: =+J39+J40 -> 286.22779 | ... Q43: =+Q39+Q40 -> 395.3024
B44: % margin | C44: =+C43/C6 -> 0.60053922 | D44: =+D43/D6 -> 0.58828941 | E44: =+E43/E6 -> 0.54663808 | F44: =+F43/F6 -> 0.49431623 | G44: =+G43/G6 -> 0.51063089 | H44: =+H43/H6 -> 0.52125 | I44: =+I43/I6 -> 0.525 | J44: =+J43/J6 -> 0.52875 | ... Q44: =+Q43/Q6 -> 0.5325
B47: EBITDA - Capex | C47: =+C25+C34 -> 229.839 | D47: =+D25+D34 -> 245.094 | E47: =+E25+E34 -> 260.999 | F47: =+F25+F34 -> 261.274 | G47: =+G25+G34 -> 295.299 | H47: =+H25+H34 -> 321.73222 | I47: =+I25+I34 -> 351.27154 | J47: =+J25+J34 -> 382.17838 | ... Q47: =+Q25+Q34 -> 527.81222
B48: EBITDA - Capex / EBITDA | C48: =+C47/C25 -> 0.99696364 | D48: =+D47/D25 -> 0.99660471 | E48: =+E47/E25 -> 0.99232749 | F48: =+F47/F25 -> 0.99597833 | G48: =+G47/G25 -> 0.9969514 | H48: =+H47/H25 -> 0.98723404 | I48: =+I47/I25 -> 0.98732394 | J48: =+J47/J25 -> 0.98741259 | ... Q48: =+Q47/Q25 -> 0.9875

Sheet Balance Sheet
B2: Rightmove plc - Balance Sheet
B4: (YE 31-Dec, £m) | C4: ='Income Statement'!C4 -> 2021 | D4: ='Income Statement'!D4 -> 2022 | E4: ='Income Statement'!E4 -> 2023 | F4: ='Income Statement'!F4 -> 2024 | G4: ='Income Statement'!G4 -> 2025 | H4: 2025 (Adj.) | I4: ='Income Statement'!H4 -> 2026 | J4: ='Income Statement'!I4 -> 2027 | K4: ='Income Statement'!J4 -> 2028 | L4: ='Income Statement'!K4 -> 2029 | M4: ='Income Statement'!L4 -> 2030 | N4: ='Income Statement'!M4 -> 2031 | O4: ='Income Statement'!N4 -> 2032 | P4: ='Income Statement'!O4 -> 2033 | ... R4: ='Income Statement'!Q4 -> 2035
B6: ASSETS
B8: Net PP&E | C8: ='PPE Schedule'!C10 -> 11.99 | D8: ='PPE Schedule'!D10 -> 10.43 | E8: ='PPE Schedule'!E10 -> 9.38 | F8: ='PPE Schedule'!F10 -> 8.38 | G8: ='PPE Schedule'!G10 -> 9.51 | H8: =G8 -> 9.51 | I8: ='PPE Schedule'!H10 -> 9.0477411 | J8: ='PPE Schedule'!I10 -> 8.5466404 | K8: ='PPE Schedule'!J10 -> 8.0053113 | L8: ='PPE Schedule'!K10 -> 7.4258124 | M8: ='PPE Schedule'!L10 -> 6.8111104 | N8: ='PPE Schedule'!M10 -> 6.1650653 | O8: ='PPE Schedule'!N10 -> 5.4923799 | P8: ='PPE Schedule'!O10 -> 4.7949621 | ... R8: ='PPE Schedule'!Q10 -> 3.3318801
B9: Goodwill (from LBO) | C9: 0 | D9: 0 | E9: 0 | F9: 0 | G9: 0 | H9: =+H46-H8-(H11+H12+H13+H14)-(H16+H17) -> 3821.6911 | I9: =H9 -> 3821.6911 | J9: =I9 -> 3821.6911 | K9: =J9 -> 3821.6911 | L9: =K9 -> 3821.6911 | M9: =L9 -> 3821.6911 | N9: =M9 -> 3821.6911 | O9: =N9 -> 3821.6911 | P9: =O9 -> 3821.6911 | ... R9: =Q9 -> 3821.6911
B10: Current Assets | C10: =C11+C12+C13+C14 -> 72.157 | D10: =D11+D12+D13+D14 -> 67.343 | E10: =E11+E12+E13+E14 -> 70.504 | F10: =F11+F12+F13+F14 -> 71.149 | G10: =G11+G12+G13+G14 -> 75.278 | H10: =H11+H12+H13+H14 -> 38.055 | I10: =I11+I12+I13+I14 -> 218.52821 | J10: =J11+J12+J13+J14 -> 393.37852 | ... R10: =R11+R12+R13+R14 -> 1301.2274
B11: Cash And Equivalents | C11: 42.985 | D11: 35.089 | E11: 33.641 | F11: 35.761 | G11: 37.223 | H11: 0 | I11: ='Cash Flow Statement'!H22 -> 177.24019 | J11: ='Cash Flow Statement'!I22 -> 349.09876 | K11: ='Cash Flow Statement'!J22 -> 524.0608 | L11: ='Cash Flow Statement'!K22 -> 717.55172 | M11: ='Cash Flow Statement'!L22 -> 917.11406 | N11: ='Cash Flow Statement'!M22 -> 1120.844 | O11: ='Cash Flow Statement'!N22 -> 1327.0678 | P11: ='Cash Flow Statement'!O22 -> 1077.4148 | ... R11: ='Cash Flow Statement'!Q22 -> 1238.3655
B12: Short Term Investments | C12: 5.003 | D12: 5.047 | E12: 5.224 | F12: 5.482 | G12: 5.683 | H12: =G12 -> 5.683 | I12: =H12 -> 5.683 | J12: =I12 -> 5.683 | K12: =J12 -> 5.683 | L12: =K12 -> 5.683 | M12: =L12 -> 5.683 | N12: =M12 -> 5.683 | O12: =N12 -> 5.683 | ... R12: =Q12 -> 5.683
B13: Accounts & Notes Receivable | C13: 17.931 | D13: 20.957 | E13: 24.896 | F13: 22.178 | G13: 25.251 | H13: =G13 -> 25.251 | I13: =I55/365*'Income Statement'!H6 -> 27.862182 | J13: =J55/365*'Income Statement'!I6 -> 30.203326 | K13: =K55/365*'Income Statement'!J6 -> 32.628058 | L13: =L55/365*'Income Statement'!K6 -> 34.928702 | M13: =M55/365*'Income Statement'!L6 -> 37.050532 | N13: =N55/365*'Income Statement'!M6 -> 38.939702 | O13: =O55/365*'Income Statement'!N6 -> 40.545422 | P13: =P55/365*'Income Statement'!O6 -> 42.036141 | ... R13: =R55/365*'Income Statement'!Q6 -> 44.7445
B14: Other Current Assets | C14: 6.238 | D14: 6.25 | E14: 6.743 | F14: 7.728 | G14: 7.121 | H14: =G14 -> 7.121 | I14: =0.01675*'Income Statement'!H6 -> 7.7428371 | J14: =0.01675*'Income Statement'!I6 -> 8.3934356 | K14: =0.01675*'Income Statement'!J6 -> 9.0672632 | L14: =0.01675*'Income Statement'!K6 -> 9.706607 | M14: =0.01675*'Income Statement'!L6 -> 10.296259 | N14: =0.01675*'Income Statement'!M6 -> 10.821255 | O14: =0.01675*'Income Statement'!N6 -> 11.267481 | P14: =0.01675*'Income Statement'!O6 -> 11.681748 | ... R14: =0.01675*'Income Statement'!Q6 -> 12.434395
B15: Long Term Assets | C15: =C16+C17 -> 23.43 | D15: =D16+D17 -> 23.987 | E15: =E16+E17 -> 24.989 | F15: =F16+F17 -> 38.969 | G15: =G16+G17 -> 43.393 | H15: =H16+H17 -> 43.393 | I15: =I16+I17 -> 43.393 | J15: =J16+J17 -> 43.393 | ... R15: =R16+R17 -> 43.393
B16: Deferred Charges, LT | C16: 2.169 | D16: 1.46 | E16: 2.383 | F16: 1.449 | G16: 1.012 | H16: =G16 -> 1.012 | I16: =H16 -> 1.012 | J16: =I16 -> 1.012 | K16: =J16 -> 1.012 | L16: =K16 -> 1.012 | M16: =L16 -> 1.012 | N16: =M16 -> 1.012 | O16: =N16 -> 1.012 | ... R16: =Q16 -> 1.012
B17: Other Long-Term Assets | C17: 21.261 | D17: 22.527 | E17: 22.606 | F17: 37.52 | G17: 42.381 | H17: =G17 -> 42.381 | I17: =H17 -> 42.381 | J17: =I17 -> 42.381 | K17: =J17 -> 42.381 | L17: =K17 -> 42.381 | M17: =L17 -> 42.381 | N17: =M17 -> 42.381 | O17: =N17 -> 42.381 | ... R17: =Q17 -> 42.381
B19: Total Assets | C19: =+C8+C10+C15 -> 107.577 | D19: =+D8+D10+D15 -> 101.76 | E19: =+E8+E10+E15 -> 104.873 | F19: =+F8+F10+F15 -> 118.498 | G19: =+G8+G10+G15 -> 128.181 | H19: =H8+H9+H10+H15 -> 3912.6491 | I19: =I8+I9+I10+I15 -> 4092.66 | J19: =J8+J9+J10+J15 -> 4267.0092 | K19: =K8+K9+K10+K15 -> 4444.5285 | L19: =L8+L9+L10+L15 -> 4640.3799 | M19: =M8+M9+M10+M15 -> 4842.039 | N19: =N8+N9+N10+N15 -> 5047.5371 | O19: =O8+O9+O10+O15 -> 5255.1402 | ... R19: =R8+R9+R10+R15 -> 5169.6433
B21: LIABILITIES & EQUITY
B23: LIABILITIES | C23: =C29+C31+C33 -> 37.045 | D23: =D29+D31+D33 -> 33.597 | E23: =E29+E31+E33 -> 35.517 | F23: =F29+F31+F33 -> 37.636 | G23: =G29+G31+G33 -> 45.883 | H23: =H29+H31+H32+H33 -> 2408.315 | I23: =I29+I31+I32+I33 -> 2347.3735 | J23: =J29+J31+J32+J33 -> 2258.6449 | K23: =K29+K31+K32+K33 -> 2149.9363 | L23: =L29+L31+L32+L33 -> 2038.0738 | M23: =M29+M31+M32+M33 -> 1912.4041 | N23: =N29+N31+N32+N33 -> 1773.8832 | O23: =O29+O31+O32+O33 -> 1623.2813 | ... R23: =R29+R31+R32+R33 -> 387.31835
B24: Accrued Exp. | C24: 0 | D24: 0 | E24: 0 | F24: 0 | G24: 0 | H24: 0 | I24: 0 | J24: 0 | K24: 0 | L24: 0 | M24: 0 | N24: 0 | O24: 0 | P24: 0 | Q24: 0 | R24: 0
B25: Short-term Borrowings | C25: 2.177 | D25: 2.327 | E25: 2.291 | F25: 2.497 | G25: 3.562 | H25: 0 | I25: 0 | J25: 0 | K25: 0 | L25: 0 | M25: 0 | N25: 0 | O25: 0 | P25: 0 | Q25: 0 | R25: 0
B26: Accounts Payable | C26: 3.056 | D26: 1.155 | E26: 2.057 | F26: 1.326 | G26: 1.826 | H26: =G26 -> 1.826 | I26: =I56/365*-'Income Statement'!H22 -> 1.8680327 | J26: =J56/365*-'Income Statement'!I22 -> 1.9906738 | K26: =K56/365*-'Income Statement'!J22 -> 2.1134083 | L26: =L56/365*-'Income Statement'!K22 -> 2.2386123 | M26: =M56/365*-'Income Statement'!L22 -> 2.3577611 | N26: =N56/365*-'Income Statement'!M22 -> 2.4779811 | O26: =O56/365*-'Income Statement'!N22 -> 2.5801632 | P26: =P56/365*-'Income Statement'!O22 -> 2.6750271 | ... R26: =R56/365*-'Income Statement'!Q22 -> 2.8473773
B27: Curr. Income Taxes Payable | C27: 10.974 | D27: 12.288 | E27: 13.508 | F27: 13.407 | G27: 16.737 | H27: =G27 -> 16.737 | I27: =0.039369*'Income Statement'!H6 -> 18.198672 | J27: =0.039369*'Income Statement'!I6 -> 19.727831 | K27: =0.039369*'Income Statement'!J6 -> 21.311587 | L27: =0.039369*'Income Statement'!K6 -> 22.814293 | M27: =0.039369*'Income Statement'!L6 -> 24.200203 | N27: =0.039369*'Income Statement'!M6 -> 25.434148 | O27: =0.039369*'Income Statement'!N6 -> 26.482952 | P27: =0.039369*'Income Statement'!O6 -> 27.456641 | ... R27: =0.039369*'Income Statement'!Q6 -> 29.225653
B28: Other Current Liabilities | C28: 11.421 | D28: 9.756 | E28: 11.708 | F28: 15.471 | G28: 18.419 | H28: =G28 -> 18.419 | I28: =0.043326*'Income Statement'!H6 -> 20.02783 | J28: =0.043326*'Income Statement'!I6 -> 21.710686 | K28: =0.043326*'Income Statement'!J6 -> 23.453627 | L28: =0.043326*'Income Statement'!K6 -> 25.10737 | M28: =0.043326*'Income Statement'!L6 -> 26.632579 | N28: =0.043326*'Income Statement'!M6 -> 27.990548 | O28: =0.043326*'Income Statement'!N6 -> 29.144768 | P28: =0.043326*'Income Statement'!O6 -> 30.216323 | ... R28: =0.043326*'Income Statement'!Q6 -> 32.16314
B29: Total Current Liabilities | C29: 27.628 | D29: 25.526 | E29: 29.564 | F29: 32.701 | G29: 40.544 | H29: =H24+H25+H26+H27+H28 -> 36.982 | I29: =I24+I25+I26+I27+I28 -> 40.094535 | J29: =J24+J25+J26+J27+J28 -> 43.429191 | K29: =K24+K25+K26+K27+K28 -> 46.878622 | L29: =L24+L25+L26+L27+L28 -> 50.160276 | M29: =M24+M25+M26+M27+M28 -> 53.190543 | N29: =N24+N25+N26+N27+N28 -> 55.902677 | O29: =O24+O25+O26+O27+O28 -> 58.207883 | ... R29: =R24+R25+R26+R27+R28 -> 64.23617
B31: Long-Term Debt | C31: 8.832 | D31: 7.242 | E31: 5.112 | F31: 3.665 | G31: 3.622 | H31: ='LBO Modelling'!D8 -> 2369.616 | I31: ='LBO Modelling'!C80 -> 2305.5619 | J31: ='LBO Modelling'!D80 -> 2213.4987 | K31: ='LBO Modelling'!E80 -> 2101.3407 | L31: ='LBO Modelling'!F80 -> 1986.1965 | M31: ='LBO Modelling'!G80 -> 1857.4966 | N31: ='LBO Modelling'!H80 -> 1716.2635 | O31: ='LBO Modelling'!I80 -> 1563.3564 | P31: ='LBO Modelling'!J80 -> 941.39587 | ... R31: ='LBO Modelling'!L80 -> 321.36518
B32: Unearned Revenue, Non-Current | C32: 0 | D32: 0 | E32: 0 | F32: 0 | G32: 0 | H32: 0 | I32: 0 | J32: 0 | K32: 0 | L32: 0 | M32: 0 | N32: 0 | O32: 0 | P32: 0 | Q32: 0 | R32: 0
B33: Other Non-Current Liabilities | C33: 0.585 | D33: 0.829 | E33: 0.841 | F33: 1.27 | G33: 1.717 | H33: =G33 -> 1.717 | I33: =H33 -> 1.717 | J33: =I33 -> 1.717 | K33: =J33 -> 1.717 | L33: =K33 -> 1.717 | M33: =L33 -> 1.717 | N33: =M33 -> 1.717 | O33: =N33 -> 1.717 | ... R33: =Q33 -> 1.717
B35: Pref. Stock, Non-Redeem. | C35: 0 | D35: 0 | E35: 0 | F35: 0 | G35: 0 | H35: 0 | I35: 0 | J35: 0 | K35: 0 | L35: 0 | M35: 0 | N35: 0 | O35: 0 | P35: 0 | Q35: 0 | R35: 0
B36: Total Pref. Equity | C36: 0 | D36: 0 | E36: 0 | F36: 0 | G36: 0 | H36: 0 | I36: 0 | J36: 0 | K36: 0 | L36: 0 | M36: 0 | N36: 0 | O36: 0 | P36: 0 | Q36: 0 | R36: 0
B38: Minority Interest | C38: 0 | D38: 0 | E38: 0 | F38: 0 | G38: 0 | H38: 0 | I38: 0 | J38: 0 | K38: 0 | L38: 0 | M38: 0 | N38: 0 | O38: 0 | P38: 0 | Q38: 0 | R38: 0
B39: Common Stock | C39: 0 | D39: 0 | E39: 0 | F39: 0 | G39: 0 | H39: 0 | I39: 0 | J39: 0 | K39: 0 | L39: 0 | M39: 0 | N39: 0 | O39: 0 | P39: 0 | Q39: 0 | R39: 0
B40: Additional Paid In Capital | C40: 0.86 | D40: 0.838 | E40: 0.814 | F40: 0.795 | G40: 0.774 | H40: ='LBO Modelling'!D12 -> 1504.3341 | I40: =H40 -> 1504.3341 | J40: =I40 -> 1504.3341 | K40: =J40 -> 1504.3341 | L40: =K40 -> 1504.3341 | M40: =L40 -> 1504.3341 | N40: =M40 -> 1504.3341 | O40: =N40 -> 1504.3341 | P40: =O40 -> 1504.3341 | ... R40: =Q40 -> 1504.3341
B41: Retained Earnings | C41: 69.1 | D41: 66.731 | E41: 67.924 | F41: 79.43 | G41: 101.67 | H41: 0 | I41: =H41+'Income Statement'!H43 -> 240.95247 | J41: =I41+'Income Statement'!I43 -> 504.0303 | K41: =J41+'Income Statement'!J43 -> 790.25809 | L41: =K41+'Income Statement'!K43 -> 1097.972 | M41: =L41+'Income Statement'!L43 -> 1425.3008 | N41: =M41+'Income Statement'!M43 -> 1769.3198 | O41: =N41+'Income Statement'!N43 -> 2127.5248 | P41: =O41+'Income Statement'!O43 -> 2498.8998 | ... R41: =Q41+'Income Statement'!Q43 -> 3277.9909
B42: Treasury Stock | C42: 0 | D42: 0 | E42: 0 | F42: 0 | G42: -20.804 | H42: 0 | I42: 0 | J42: 0 | K42: 0 | L42: 0 | M42: 0 | N42: 0 | O42: 0 | P42: 0 | Q42: 0 | R42: 0
B43: Comprehensive Inc. and Other | C43: 0.572 | D43: 0.594 | E43: 0.618 | F43: 0.637 | G43: 0.658 | H43: 0 | I43: 0 | J43: 0 | K43: 0 | L43: 0 | M43: 0 | N43: 0 | O43: 0 | P43: 0 | Q43: 0 | R43: 0
B44: Total Equity | C44: 70.532 | D44: 68.163 | E44: 69.356 | F44: 80.862 | G44: 82.298 | H44: =H35+H36+H38+H39+H40+H41+H42+H43 -> 1504.3341 | I44: =I35+I36+I38+I39+I40+I41+I42+I43 -> 1745.2865 | J44: =J35+J36+J38+J39+J40+J41+J42+J43 -> 2008.3644 | K44: =K35+K36+K38+K39+K40+K41+K42+K43 -> 2294.5922 | L44: =L35+L36+L38+L39+L40+L41+L42+L43 -> 2602.3061 | M44: =M35+M36+M38+M39+M40+M41+M42+M43 -> 2929.6349 | N44: =N35+N36+N38+N39+N40+N41+N42+N43 -> 3273.6539 | O44: =O35+O36+O38+O39+O40+O41+O42+O43 -> 3631.8589 | ... R44: =R35+R36+R38+R39+R40+R41+R42+R43 -> 4782.325
B46: Total Liab. & Equity | C46: =+C23+C44 -> 107.577 | D46: =+D23+D44 -> 101.76 | E46: =+E23+E44 -> 104.873 | F46: =+F23+F44 -> 118.498 | G46: =+G23+G44 -> 128.181 | H46: =H23+H44 -> 3912.6491 | I46: =I23+I44 -> 4092.66 | J46: =J23+J44 -> 4267.0092 | K46: =K23+K44 -> 4444.5285 | L46: =L23+L44 -> 4640.3799 | M46: =M23+M44 -> 4842.039 | N46: =N23+N44 -> 5047.5371 | O46: =O23+O44 -> 5255.1402 | ... R46: =R23+R44 -> 5169.6433
B47: Balance Check (Assets - L&E) | C47: =+C19-C46 -> 0 | D47: =+D19-D46 -> 0 | E47: =+E19-E46 -> 0 | F47: =+F19-F46 -> 0 | G47: =+G19-G46 -> 0 | H47: =H19-H46 -> 0 | I47: =I19-I46 -> 0 | J47: =J19-J46 -> 0 | K47: =K19-K46 -> 0 | L47: =L19-L46 -> 0 | M47: =M19-M46 -> 0 | N47: =N19-N46 -> 0 | O47: =O19-O46 -> 0 | ... R47: =R19-R46 -> 0
B52: Working Capital Days Assumptions
C54: =C4 -> 2021 | D54: =D4 -> 2022 | E54: =E4 -> 2023 | F54: =F4 -> 2024 | G54: =G4 -> 2025 | H54: =H4 -> 2025 (Adj.) | I54: =I4 -> 2026 | J54: =J4 -> 2027 | ... R54: =R4 -> 2035
B55: AR Days | C55: =+C11/'Income Statement'!C6*365 -> 51.4603 | D55: =+D11/'Income Statement'!D6*365 -> 38.504624 | E55: =+E11/'Income Statement'!E6*365 -> 33.704161 | F55: =+F11/'Income Statement'!F6*365 -> 33.478758 | G55: =+G11/'Income Statement'!G6*365 -> 31.958288 | I55: 22 | J55: =I55 -> 22 | K55: =J55 -> 22 | L55: =K55 -> 22 | M55: =L55 -> 22 | N55: =M55 -> 22 | O55: =N55 -> 22 | P55: =O55 -> 22 | Q55: =P55 -> 22 | R55: =Q55 -> 22
B56: AP Days | C56: =+C31/(-1*'Income Statement'!C22)*365 -> 42.000156 | D56: =+D31/(-1*'Income Statement'!D22)*365 -> 30.490345 | E56: =+E31/(-1*'Income Statement'!E22)*365 -> 18.420076 | F56: =+F31/(-1*'Income Statement'!F22)*365 -> 10.487766 | G56: =+G31/(-1*'Income Statement'!G22)*365 -> 10.254495 | I56: 5 | J56: =I56 -> 5 | K56: =J56 -> 5 | L56: =K56 -> 5 | M56: =L56 -> 5 | N56: =M56 -> 5 | O56: =N56 -> 5 | P56: =O56 -> 5 | Q56: =P56 -> 5 | R56: =Q56 -> 5
...

Sheet Cash Flow Statement
B2: Rightmove plc - Cash Flow Statement
B4: (YE 31-Dec, £m) | C4: ='Income Statement'!C4 -> 2021 | D4: ='Income Statement'!D4 -> 2022 | E4: ='Income Statement'!E4 -> 2023 | F4: ='Income Statement'!F4 -> 2024 | G4: ='Income Statement'!G4 -> 2025 | H4: ='Income Statement'!H4 -> 2026 | I4: ='Income Statement'!I4 -> 2027 | J4: ='Income Statement'!J4 -> 2028 | ... Q4: ='Income Statement'!Q4 -> 2035
B6: Net Income | C6: ='Income Statement'!C43 -> 183.096 | D6: ='Income Statement'!D43 -> 195.678 | E6: ='Income Statement'!E43 -> 199.149 | F6: ='Income Statement'!F43 -> 192.725 | G6: ='Income Statement'!G43 -> 217.084 | H6: ='Income Statement'!H43 -> 240.95247 | I6: ='Income Statement'!I43 -> 263.07783 | J6: ='Income Statement'!J43 -> 286.22779 | ... Q6: ='Income Statement'!Q43 -> 395.3024
B8: Depreciation & Amort., Total | C8: 4.439 | D8: 4.586 | E8: 4.984 | F8: 5.999 | G8: 8.328 | H8: =-'Income Statement'!H28 -> 4.6225893 | I8: =-'Income Statement'!I28 -> 5.0110063 | J8: =-'Income Statement'!J28 -> 5.4132915 | K8: =-'Income Statement'!K28 -> 5.7949893 | L8: =-'Income Statement'!L28 -> 6.14702 | M8: =-'Income Statement'!M28 -> 6.4604506 | N8: =-'Income Statement'!N28 -> 6.7268541 | O8: =-'Income Statement'!O28 -> 6.9741779 | ... Q8: =-'Income Statement'!Q28 -> 7.4235193
B9: Other Non-Cash Adj | C9: 2.059 | D9: 4.112 | E9: 5.004 | F9: 10.113 | G9: 10.917 | H9: 0 | I9: 0 | J9: 0 | K9: 0 | L9: 0 | M9: 0 | N9: 0 | O9: 0 | P9: 0 | Q9: 0
B10: Changes in Non-Cash Capital | C10: 5.447 | D10: -5.981 | E10: -0.734 | F10: 4.849 | G10: 2.422 | H10: ='Balance Sheet'!H61-'Balance Sheet'!I61 -> -0.12048428 | I10: ='Balance Sheet'!I61-'Balance Sheet'!J61 -> 0.34291346 | J10: ='Balance Sheet'!J61-'Balance Sheet'!K61 -> 0.35087154 | K10: ='Balance Sheet'!K61-'Balance Sheet'!L61 -> 0.34166586 | L10: ='Balance Sheet'!L61-'Balance Sheet'!M61 -> 0.31878644 | M10: ='Balance Sheet'!M61-'Balance Sheet'!N61 -> 0.29796728 | N10: ='Balance Sheet'!N61-'Balance Sheet'!O61 -> 0.25326029 | O10: ='Balance Sheet'!O61-'Balance Sheet'!P61 -> 0.23512193 | ... Q10: ='Balance Sheet'!Q61-'Balance Sheet'!R61 -> 0.20555171
B12: Cash Flow from Operating Activities | C12: =SUM(C6:C10) -> 195.041 | D12: =SUM(D6:D10) -> 198.395 | E12: =SUM(E6:E10) -> 208.403 | F12: =SUM(F6:F10) -> 213.686 | G12: =SUM(G6:G10) -> 238.751 | H12: =SUM(H6:H10) -> 245.45457 | I12: =SUM(I6:I10) -> 268.43175 | J12: =SUM(J6:J10) -> 291.99195 | ... Q12: =SUM(Q6:Q10) -> 402.93147
B14: Capital Expenditure | C14: =-'PPE Schedule'!C6 -> -0.7 | D14: =-'PPE Schedule'!D6 -> -0.835 | E14: =-'PPE Schedule'!E6 -> -2.018 | F14: =-'PPE Schedule'!F6 -> -1.055 | G14: =-'PPE Schedule'!G6 -> -0.903 | H14: =-'PPE Schedule'!H6 -> -4.1603304 | I14: =-'PPE Schedule'!I6 -> -4.5099057 | J14: =-'PPE Schedule'!J6 -> -4.8719623 | ... Q14: =-'PPE Schedule'!Q6 -> -6.6811674
B15: Cash Flow from Investing Activities | C15: -0.7 | D15: -0.835 | E15: -2.018 | F15: -4.055 | G15: -0.903 | H15: =H14 -> -4.1603304 | I15: =I14 -> -4.5099057 | J15: =J14 -> -4.8719623 | K15: =K14 -> -5.2154903 | L15: =L14 -> -5.532318 | M15: =M14 -> -5.8144056 | N15: =N14 -> -6.0541687 | O15: =O14 -> -6.2767601 | ... Q15: =Q14 -> -6.6811674
B17: Debt Repayment | C17: ='Debt Schedule'!C7 -> -1.59 | D17: ='Debt Schedule'!D7 -> -1.59 | E17: ='Debt Schedule'!E7 -> -2.13 | F17: ='Debt Schedule'!F7 -> -1.447 | G17: ='Debt Schedule'!G7 -> -0.043 | H17: ='LBO Modelling'!C79 -> -64.054052 | I17: ='LBO Modelling'!D79 -> -92.063275 | J17: ='LBO Modelling'!E79 -> -112.15795 | K17: ='LBO Modelling'!F79 -> -115.14417 | L17: ='LBO Modelling'!G79 -> -128.69997 | M17: ='LBO Modelling'!H79 -> -141.23307 | N17: ='LBO Modelling'!I79 -> -152.9071 | O17: ='LBO Modelling'!J79 -> -621.96055 | ... Q17: ='LBO Modelling'!L79 -> -283.49033
B18: Cash Flow from Financing Activities | C18: -243.022 | D18: -203.4 | E18: -206.507 | F18: -191.924 | G18: -227.093 | H18: =H17 -> -64.054052 | I18: =I17 -> -92.063275 | J18: =J17 -> -112.15795 | K18: =K17 -> -115.14417 | L18: =L17 -> -128.69997 | M18: =M17 -> -141.23307 | N18: =N17 -> -152.9071 | O18: =O17 -> -621.96055 | ... Q18: =Q17 -> -283.49033
B20: Net Change in Cash | C20: =+C12+C15+C18 -> -48.681 | D20: =+D12+D15+D18 -> -5.84 | E20: =+E12+E15+E18 -> -0.122 | F20: =+F12+F15+F18 -> 17.707 | G20: =+G12+G15+G18 -> 10.755 | H20: =H12+H15+H18 -> 177.24019 | I20: =I12+I15+I18 -> 171.85857 | J20: =J12+J15+J18 -> 174.96203 | K20: =K12+K15+K18 -> 193.49092 | L20: =L12+L15+L18 -> 199.56234 | M20: =M12+M15+M18 -> 203.72994 | N20: =N12+N15+N18 -> 206.22383 | O20: =O12+O15+O18 -> -249.65304 | ... Q20: =Q12+Q15+Q18 -> 112.75998
B21: Opening Cash | C21: 12.418 | D21: =+C22 -> -36.263 | E21: =+D22 -> -42.103 | F21: =+E22 -> -42.225 | G21: =+F22 -> -24.518 | H21: ='Balance Sheet'!H11 -> 0 | I21: =H22 -> 177.24019 | J21: =I22 -> 349.09876 | K21: =J22 -> 524.0608 | L21: =K22 -> 717.55172 | M21: =L22 -> 917.11406 | N21: =M22 -> 1120.844 | O21: =N22 -> 1327.0678 | P21: =O22 -> 1077.4148 | Q21: =P22 -> 1125.6055
B22: Closing Cash | C22: =+C20+C21 -> -36.263 | D22: =+D20+D21 -> -42.103 | E22: =+E20+E21 -> -42.225 | F22: =+F20+F21 -> -24.518 | G22: =+G20+G21 -> -13.763 | H22: =H20+H21 -> 177.24019 | I22: =I20+I21 -> 349.09876 | J22: =J20+J21 -> 524.0608 | K22: =K20+K21 -> 717.55172 | L22: =L20+L21 -> 917.11406 | M22: =M20+M21 -> 1120.844 | N22: =N20+N21 -> 1327.0678 | O22: =O20+O21 -> 1077.4148 | ... Q22: =Q20+Q21 -> 1238.3655
B25: Supplemental Items
B26: Cash Interest Paid | C26: 0.209 | D26: 0.451 | E26: 0.479 | F26: 0.538 | G26: 0.535
B27: Cash Taxes Paid | C27: 41.611 | D27: 45.622 | E27: 60.979 | F27: 65.809 | G27: 71.181
B28: Free Cash Flow | C28: 194.339 | D28: 197.563 | E28: 206.387 | F28: 212.619 | G28: 237.831
B29: Change in Net Working Capital | C29: 5.447 | D29: -5.981 | E29: -0.734 | F29: 4.849 | G29: 2.422

Sheet PPE Schedule
B2: PPE Schedule
B4: (£m) | C4: ='Income Statement'!C4 -> 2021 | D4: ='Income Statement'!D4 -> 2022 | E4: ='Income Statement'!E4 -> 2023 | F4: ='Income Statement'!F4 -> 2024 | G4: ='Income Statement'!G4 -> 2025 | H4: ='Income Statement'!H4 -> 2026 | I4: ='Income Statement'!I4 -> 2027 | J4: ='Income Statement'!J4 -> 2028 | ... Q4: ='Income Statement'!Q4 -> 2035
B5: Opening Balance | C5: 13.9 | D5: =C10 -> 11.99 | E5: =D10 -> 10.43 | F5: =E10 -> 9.38 | G5: =F10 -> 8.38 | H5: =G10 -> 9.51 | I5: =H10 -> 9.0477411 | J5: =I10 -> 8.5466404 | K5: =J10 -> 8.0053113 | ... Q5: =P10 -> 4.0742321
B6: (+) Additions (Capex) | C6: =-'Income Statement'!C34 -> 0.7 | D6: =-'Income Statement'!D34 -> 0.835 | E6: =-'Income Statement'!E34 -> 2.018 | F6: =-'Income Statement'!F34 -> 1.055 | G6: =-'Income Statement'!G34 -> 0.903 | H6: =-'Income Statement'!H34 -> 4.1603304 | I6: =-'Income Statement'!I34 -> 4.5099057 | J6: =-'Income Statement'!J34 -> 4.8719623 | ... Q6: =-'Income Statement'!Q34 -> 6.6811674
B7: (+) Lease Additions / Other | C7: 0.838 | D7: 1.109 | E7: 0.356 | F7: 1.558 | G7: 4.164 | H7: 0 | I7: 0 | J7: 0 | K7: 0 | L7: 0 | M7: 0 | N7: 0 | O7: 0 | P7: 0 | Q7: 0
B8: (-) Sale | C8: 0 | D8: 0 | E8: 0 | F8: 0 | G8: 0 | H8: 0 | I8: 0 | J8: 0 | K8: 0 | L8: 0 | M8: 0 | N8: 0 | O8: 0 | P8: 0 | Q8: 0
B9: (-) Depreciation | C9: -3.448 | D9: -3.504 | E9: -3.424 | F9: -3.613 | G9: -3.937 | H9: ='Income Statement'!H28 -> -4.6225893 | I9: ='Income Statement'!I28 -> -5.0110063 | J9: ='Income Statement'!J28 -> -5.4132915 | K9: ='Income Statement'!K28 -> -5.7949893 | L9: ='Income Statement'!L28 -> -6.14702 | M9: ='Income Statement'!M28 -> -6.4604506 | N9: ='Income Statement'!N28 -> -6.7268541 | O9: ='Income Statement'!O28 -> -6.9741779 | ... Q9: ='Income Statement'!Q28 -> -7.4235193
B10: Closing Balance | C10: 11.99 | D10: 10.43 | E10: 9.38 | F10: 8.38 | G10: 9.51 | H10: =+H5+H6+H7+H8+H9 -> 9.0477411 | I10: =+I5+I6+I7+I8+I9 -> 8.5466404 | J10: =+J5+J6+J7+J8+J9 -> 8.0053113 | K10: =+K5+K6+K7+K8+K9 -> 7.4258124 | L10: =+L5+L6+L7+L8+L9 -> 6.8111104 | M10: =+M5+M6+M7+M8+M9 -> 6.1650653 | N10: =+N5+N6+N7+N8+N9 -> 5.4923799 | O10: =+O5+O6+O7+O8+O9 -> 4.7949621 | ... Q10: =+Q5+Q6+Q7+Q8+Q9 -> 3.3318801
B12: Note: Lease Additions captures IFRS 16 right-of-use asset additions and other PP&E movements
B13: not included in cash capex. Historical values plugged to Bloomberg closing balances.
B14: Historical lease additions plugged to reconcile to Bloomberg closing balances.
B15: Projected lease additions = 0 (simplification: existing leases depreciate down).
B16: PPE going to £0 by 2035 is immaterial vs. £3.5bn enterprise value.

Sheet Debt Schedule
B2: Debt Schedule (Pre-LBO)
B4: (£m) | C4: ='Income Statement'!C4 -> 2021 | D4: ='Income Statement'!D4 -> 2022 | E4: ='Income Statement'!E4 -> 2023 | F4: ='Income Statement'!F4 -> 2024 | G4: ='Income Statement'!G4 -> 2025
B5: Opening Balance | C5: =+C8-C7-C6 -> 10.422 | D5: =C8 -> 8.832 | E5: =D8 -> 7.242 | F5: =E8 -> 5.112 | G5: =F8 -> 3.665
B6: (+) Additions | C6: 0 | D6: 0 | E6: 0 | F6: 0 | G6: 0
B7: (-) Repayment | C7: =+D7 -> -1.59 | D7: =+D8-D5 -> -1.59 | E7: =+E8-E5 -> -2.13 | F7: =+F8-F5 -> -1.447 | G7: =+G8-G5 -> -0.043
B8: Closing Balance | C8: 8.832 | D8: 7.242 | E8: 5.112 | F8: 3.665 | G8: 3.622
B10: Avg Interest Rate (pre-LBO) | C10: 0.075
B12: Interest Expense | C12: =+C5*$C$10 -> 0.78165 | D12: =+D5*$C$10 -> 0.6624 | E12: =+E5*$C$10 -> 0.54315 | F12: =+F5*$C$10 -> 0.3834 | G12: =+G5*$C$10 -> 0.274875
B14: NOTE: This sheet shows the PRE-LBO debt structure only (2021-2025).
B15: At LBO close (end-2025), Rightmove's existing £3.6m of debt is repaid as part of the
B16: transaction and replaced with a new LBO capital structure: £1,333m Senior Debt (4.5x
B17: LTM EBITDA at 7.5%, 7-year amortising) + £444m Subordinated Debt (1.5x at 9.5%, 8-year
B18: bullet). The full post-LBO debt schedule lives in the 'LBO Modelling' sheet, rows
B19: 26-58. Interest expense in IS!37 and debt repayments in CF!17 pull from there.

Sheet LBO Modelling
B2: Rightmove plc - LBO Transaction & Debt Schedule
D3: (£m)
B4: LTM EBITDA (2025A) | D4: ='Income Statement'!G25 -> 296.202 | I4: Other Inputs
B5: EBITDA FY+1 (2026E) | D5: =+'Income Statement'!H25 -> 325.89255 | I5: Senior Amortisation % | K5: =Assumptions!C14 -> 0.05 | L5: p.a. of original balance
B6: Entry Multiple (LTM EV/EBITDA) | C6: =Assumptions!C9 -> 12.5 | I6: Cash Sweep % | K6: =Assumptions!C15 -> 0.5 | L6: of surplus cash to Senior
B7: Leverage (Total Debt / LTM EBITDA) | C7: =Assumptions!C11 -> 8 | I7: Revolver Capacity (£m) | K7: =Assumptions!C16 -> 200 | L7: undrawn at close
B8: Total LBO Debt | D8: =+D4*C7 -> 2369.616 | I8: Revolver Interest Rate | K8: =Assumptions!C17 -> 0.075 | L8: on drawn balance
B9: Senior Debt | C9: =Assumptions!C12 -> 5.5 | D9: =+C9*D4 -> 1629.111 | E9: =Assumptions!F12 -> 0.065 | F9: 10+ years | G9: =+D9*E9 -> 105.89221 | I9: Revolver Commitment Fee | K9: =Assumptions!C18 -> 0.005 | L9: on undrawn balance
B10: Subordinated Debt | C10: =C7-C9 -> 2.5 | D10: =+C10*D4 -> 740.505 | E10: =Assumptions!F13 -> 0.095 | F10: 8 years | G10: =+D10*E10 -> 70.347975
B11: Enterprise Value | D11: =+C6*D4 -> 3702.525 | E11: % Equity: | F11: =D12/D14 -> 0.38832046 | G11: =+(G9+G10)/D8 -> 0.074375 | H11: Avg Cost of Debt
B12: Equity Investment (Sponsor) | D12: =+D14-D8 -> 1504.3341 | E12: % Debt: | F12: =D8/D14 -> 0.61167954
B13: Acquisition Cost | D13: =G22-D11 -> 171.42507
B14: TOTAL ACQUISITION PRICE | D14: =SUM(D11+D13) -> 3873.9501
B16: SOURCES | F16: USES
B17: Senior Debt (5.0x LTM EBITDA) | C17: =D4*C9 -> 1629.111 | D17: =E4*D9 -> 0 | F17: Purchase price | G17: =D11 -> 3702.525
B18: Subordinated Debt (2.0x LTM EBITDA) | C18: =D4*C10 -> 740.505 | F18: Repay Existing Debt | G18: ='Balance Sheet'!G25+'Balance Sheet'!G31 -> 7.184
B19: Sponsor Equity | C19: =G22-C17-C18 -> 1504.3341 | E19: =Assumptions!C21 -> 0.025 | F19: Transaction Fees (2.5% EV) | G19: =D14*E19 -> 96.848752
E20: =Assumptions!C22 -> 0.02 | F20: Financing Fees (2.0% debt) | G20: =(C17+C18)*Assumptions!C22 -> 47.39232
F21: Min Cash at Close | G21: =Assumptions!C23 -> 20
B22: Total Sources | C22: =C17+C18+C19 -> 3873.9501 | F22: Total Uses | G22: =SUM(G17:G21) -> 3873.9501
B24: (YE 31-Dec, £m) | C24: ='Income Statement'!H4 -> 2026 | D24: ='Income Statement'!I4 -> 2027 | E24: ='Income Statement'!J4 -> 2028 | F24: ='Income Statement'!K4 -> 2029 | G24: ='Income Statement'!L4 -> 2030 | H24: ='Income Statement'!M4 -> 2031 | I24: ='Income Statement'!N4 -> 2032 | J24: ='Income Statement'!O4 -> 2033 | ... L24: ='Income Statement'!Q4 -> 2035
B26: Cash Flow Before Debt Service | C26: =DCF!D20 -> 241.29424 | D26: =DCF!E20 -> 263.92185 | E26: =DCF!F20 -> 287.11999 | F26: =DCF!G20 -> 308.63509 | G26: =DCF!H20 -> 328.26231 | H26: =DCF!I20 -> 344.96301 | I26: =DCF!J20 -> 359.13093 | J26: =DCF!K20 -> 372.30751 | ... L26: =DCF!M20 -> 396.25031
B28: Less:
B29: Interest Payments | C29: =+C78 -> -177.24019 | D29: =+D78 -> -173.16368 | E29: =+E78 -> -167.14979 | F29: =+F78 -> -159.8023 | G29: =+G78 -> -152.31793 | H29: =+H78 -> -143.95243 | I29: =+I78 -> -134.77228 | J29: =+J78 -> -124.83332 | ... L29: =+L78 -> -40.640396
B30: All Debt Repayments / (Draws) | C30: =+C79 -> -64.054052 | D30: =+D79 -> -92.063275 | E30: =+E79 -> -112.15795 | F30: =+F79 -> -115.14417 | G30: =+G79 -> -128.69997 | H30: =+H79 -> -141.23307 | I30: =+I79 -> -152.9071 | J30: =+J79 -> -621.96055 | ... L30: =+L79 -> -283.49033
B33: Cash to Equity (after all debt service) | C33: =+C26+C29+C30 -> 0 | D33: =+D26+D29+D30 -> -1.3051124 | E33: =+E26+E29+E30 -> 7.8122442 | F33: =+F26+F29+F30 -> 33.688624 | G33: =+G26+G29+G30 -> 47.244415 | H33: =+H26+H29+H30 -> 59.777515 | I33: =+I26+I29+I30 -> 71.451549 | J33: =+J26+J29+J30 -> -374.48635 | ... L33: =+L26+L29+L30 -> 72.119584
B36: Senior Debt
B37: Period | C37: 1 | D37: =+C37+1 -> 2 | E37: =+D37+1 -> 3 | F37: =+E37+1 -> 4 | G37: =+F37+1 -> 5 | H37: =+G37+1 -> 6 | I37: =+H37+1 -> 7 | J37: =+I37+1 -> 8 | K37: =+J37+1 -> 9 | L37: =+K37+1 -> 10
B38: (£m) | C38: ='Income Statement'!H4 -> 2026 | D38: ='Income Statement'!I4 -> 2027 | E38: ='Income Statement'!J4 -> 2028 | F38: ='Income Statement'!K4 -> 2029 | G38: ='Income Statement'!L4 -> 2030 | H38: ='Income Statement'!M4 -> 2031 | I38: ='Income Statement'!N4 -> 2032 | J38: ='Income Statement'!O4 -> 2033 | ... L38: ='Income Statement'!Q4 -> 2035
B39: Opening Balance | C39: =+D9 -> 1629.111 | D39: =C43 -> 1547.6554 | E39: =D43 -> 1461.5486 | F39: =E43 -> 1360.8357 | G39: =F43 -> 1245.6915 | H39: =G43 -> 1116.9916 | I39: =H43 -> 975.75852 | J39: =I43 -> 822.85142 | K39: =J43 -> 741.39587 | L39: =K43 -> 539.89791
B40: (+) Additions | C40: 0 | D40: 0 | E40: 0 | F40: 0 | G40: 0 | H40: 0 | I40: 0 | J40: 0 | K40: 0 | L40: 0
B41: (-) Mandatory Repayment | C41: =-MIN(C39+C40, $D$9*$K$5) -> -81.45555 | D41: =-MIN(D39+D40, $D$9*$K$5) -> -81.45555 | E41: =-MIN(E39+E40, $D$9*$K$5) -> -81.45555 | F41: =-MIN(F39+F40, $D$9*$K$5) -> -81.45555 | G41: =-MIN(G39+G40, $D$9*$K$5) -> -81.45555 | H41: =-MIN(H39+H40, $D$9*$K$5) -> -81.45555 | I41: =-MIN(I39+I40, $D$9*$K$5) -> -81.45555 | J41: =-MIN(J39+J40, $D$9*$K$5) -> -81.45555 | ... L41: =-MIN(L39+L40, $D$9*$K$5) -> -81.45555
B42: (-) Cash Sweep | C42: =-MIN(C39+C40+C41,$K$6*MAX(0,C26-C47-C72-C59-C60+C41+C67)) -> 0 | D42: =-MIN(D39+D40+D41,$K$6*MAX(0,D26-D47-D72-D59-D60+D41+D67)) -> -4.6513064 | E42: =-MIN(E39+E40+E41,$K$6*MAX(0,E26-E47-E72-E59-E60+E41+E67)) -> -19.257324 | F42: =-MIN(F39+F40+F41,$K$6*MAX(0,F26-F47-F72-F59-F60+F41+F67)) -> -33.688624 | G42: =-MIN(G39+G40+G41,$K$6*MAX(0,G26-G47-G72-G59-G60+G41+G67)) -> -47.244415 | H42: =-MIN(H39+H40+H41,$K$6*MAX(0,H26-H47-H72-H59-H60+H41+H67)) -> -59.777515 | I42: =-MIN(I39+I40+I41,$K$6*MAX(0,I26-I47-I72-I59-I60+I41+I67)) -> -71.451549 | J42: =-MIN(J39+J40+J41,$K$6*MAX(0,J26-J47-J72-J59-J60+J41+J67)) -> 0 | ... L42: =-MIN(L39+L40+L41,$K$6*MAX(0,L26-L47-L72-L59-L60+L41+L67)) -> -137.07718
B43: Closing Balance | C43: =+C39+C40+C41+C42 -> 1547.6554 | D43: =+D39+D40+D41+D42 -> 1461.5486 | E43: =+E39+E40+E41+E42 -> 1360.8357 | F43: =+F39+F40+F41+F42 -> 1245.6915 | G43: =+G39+G40+G41+G42 -> 1116.9916 | H43: =+H39+H40+H41+H42 -> 975.75852 | I43: =+I39+I40+I41+I42 -> 822.85142 | J43: =+J39+J40+J41+J42 -> 741.39587 | ... L43: =+L39+L40+L41+L42 -> 321.36518
B45: Interest Rate | C45: =+E9 -> 0.065
B47: Interest Expense (Senior) | C47: =+C39*$C$45 -> 105.89221 | D47: =+D39*$C$45 -> 100.5976 | E47: =+E39*$C$45 -> 95.000659 | F47: =+F39*$C$45 -> 88.454322 | G47: =+G39*$C$45 -> 80.96995 | H47: =+H39*$C$45 -> 72.604453 | I47: =+I39*$C$45 -> 63.424304 | J47: =+J39*$C$45 -> 53.485342 | ... L47: =+L39*$C$45 -> 35.093364
B49: Revolver
B50: Period | C50: 1 | D50: 2 | E50: 3 | F50: 4 | G50: 5 | H50: 6 | I50: 7 | J50: 8 | K50: 9 | L50: 10
B51: (£m) | C51: ='Income Statement'!H4 -> 2026 | D51: ='Income Statement'!I4 -> 2027 | E51: ='Income Statement'!J4 -> 2028 | F51: ='Income Statement'!K4 -> 2029 | G51: ='Income Statement'!L4 -> 2030 | H51: ='Income Statement'!M4 -> 2031 | I51: ='Income Statement'!N4 -> 2032 | J51: ='Income Statement'!O4 -> 2033 | ... L51: ='Income Statement'!Q4 -> 2035
B52: Opening Balance | C52: =0 -> 0 | D52: =C55 -> 17.401498 | E52: =D55 -> 11.445079 | F52: =E55 -> 0 | G52: =F55 -> 0 | H52: =G55 -> 0 | I52: =H55 -> 0 | J52: =I55 -> 0 | K52: =J55 -> 200 | L52: =K55 -> 64.957595
...

Sheet PE Returns analysis
A1: Rightmove plc
A2: PE Returns Analysis - 5-Year Hold (Exit YE 2030)
A4: 5-Year Exit Scenario
A5: Entry Multiple (LTM EV/EBITDA) | C5: ='LBO Modelling'!C6 -> 12.5
A6: EBITDA at Entry (LTM 2025A) | C6: ='LBO Modelling'!D4 -> 296.202
A7: Exit Multiple (assumed = entry) | C7: =Assumptions!C10 -> 12.5
A8: EBITDA at Exit (2030E) | C8: ='Income Statement'!L25 -> 442.58544
A9: Enterprise Value at Exit | C9: =+C7*C8 -> 5532.318
A10: Less: Net Debt at Exit | C10: ='Balance Sheet'!M63 -> 934.69952
A11: Equity Value at Exit | C11: =+C9-C10 -> 4597.6185
A13: IRR Calculation
C14: 46022 | D14: =C14+365 -> 46387 | E14: =D14+365 -> 46752 | F14: =E14+365 -> 47117 | G14: =F14+365 -> 47482 | H14: =G14+365 -> 47847
C15: Entry | D15: 2026 | E15: 2027 | F15: 2028 | G15: 2029 | H15: 2030
A17: Sponsor Cash Flows
A18: Initial Equity Investment | C18: =-'LBO Modelling'!D12 -> -1504.3341
A19: Equity Proceeds at Exit | H19: =+C11 -> 4597.6185
A20: Total Cash Flows | C20: =C18 -> -1504.3341 | D20: 0 | E20: 0 | F20: 0 | G20: 0 | H20: =H19 -> 4597.6185
A22: IRR (5-year) | C22: =XIRR(C20:H20,C14:H14) -> 0.25036765
A23: MOIC (Money Multiple) | C23: =H19/-C18 -> 3.0562483
A26: Returns Summary
A27: Entry Equity Investment | C27: =-C18 -> 1504.3341
A28: Exit Equity Value | C28: =+H19 -> 4597.6185
A29: Total Equity Gain | C29: =C28-C27 -> 3093.2844
A31: Deal Sources of Returns
A32: EBITDA Growth Contribution (£m) | C32: =(C8-C6)*C5 -> 1829.793
A33: Multiple Expansion (£m) | C33: =(C7-C5)*C8 -> 0
A34: Net Debt Paydown (£m) | C34: ='LBO Modelling'!D8-'Balance Sheet'!M27+'Balance Sheet'!M13 -> 2382.4663

Sheet Sheet1
B3: Entry EV £3,703m EV/EBITDA 12.5x Debt (6.0x) £1,777m Equity in £1,629m Hold 5 years (exit 2030)
C4: Bear | D4: Base | E4: Bull
B5: Key driver | C5: Mortgage rate drag, AI capex headwind, margin pressure | D5: Steady subscription uplift, stable market share, margin recovery | E5: New verticals monetised, AI-driven ARPA growth, re-rate at exit
B6: Revenue CAGR (2025-2030) | C6: 0.0423 | D6: 0.0766 | E6: 0.0998
B7: Revenue 2030E | C7: £523m | D7: £615m | E7: £684m
B8: EBITDA 2030E | C8: £366m | D8: £443m | E8: £503m
B9: Margin | C9: 0.7 | D9: 0.72 | E9: 0.735
B10: Exit EV | C10: £4,026m | D10: £5,532m | E10: £6,785m
B11: Exit Multiple (EV/EBITDA) | C11: 11.0x | D11: 12.5x | E11: 13.5x
B12: Net debt at Exit | C12: £826m | D12: £638m | E12: £494m
B13: IRR | C13: 0.145 | D13: 0.246 | E13: 0.31
B14: MOIC | C14: 1.96x | D14: 3.00x | E14: 3.86x
B16: SOURCES | D16: USES
B17: Senior Debt (5.0x LTM EBITDA) | C17: 1629.111 | D17: Purchase price | E17: 3702.525
B18: Subordinated Debt (2.0x LTM EBITDA) | C18: 740.505 | D18: Repay Existing Debt | E18: 7.184
B19: Sponsor Equity | C19: 1504.3341 | D19: Transaction Fees (2.5% EV) | E19: 96.848752
D20: Financing Fees (2.0% debt) | E20: 47.39232
D21: Min Cash at Close | E21: 20
B22: Total Sources | C22: 3873.9501 | D22: Total Uses | E22: 3873.9501

Sheet Comps
B2: TRADING COMPARABLES (Property Portal & Digital Marketplace Peers)
B3: Company | C3: Geography | D3: EV (£bn) | E3: EV/EBITDA LTM | F3: EBITDA Margin | G3: Rev Growth | H3: Justification
B4: REA Group (ASX:REA) | C4: Australia | D4: £19.3bn | E4: 23.46 | F4: 0.55 | G4: 0.12 | H4: #1 Australian portal; closest structural analog. Premium multiple reflects stronger ARPA monetisation & vendor-paid model. Benchmark ceiling.
B5: Scout24 SE (XETRA:G24.DE) | C5: Germany | D5: £8.0bn | E5: 13.92 | F5: 0.62 | G5: 0.15 | H5: #1 German residential/commercial portal. Post-ImmoScout focus. High margin & platform diversification. Most comparable model ex-UK.
B6: Hemnet Group AB (STO:HEM.ST) | C6: Sweden | D6: £2.2bn | E6: 15.75 | F6: 0.52 | G6: 0.14 | H6: #1 Nordic portal; vendor-paid ads driving rapid ARPU expansion. Smaller scale but high-growth premium justified.
B7: Zillow Group (NASDAQ:Z) | C7: USA | D7: £7.4bn | E7: 25.85 | F7: 0.29 | G7: 0.18 | H7: Leading US portal. Lower margin due to buyer agent model; included for breadth. Lower relevance to UK pure-play.
B8: CoStar Group (NASDAQ:CSGP) | C8: USA/UK | D8: £24.0bn | E8: 49.1 | F8: 0.18 | G8: 0.13 | H8: Commercial RE data + residential portals (Homes.com). High growth but low margin; strategic read-through for OTM threat.
B9: Rightmove (RMV.L) — CURRENT | C9: UK | D9: £3.7bn | E9: ='LBO Modelling'!C6 -> 12.5 | F9: ='Income Statement'!G26 -> 0.6967344 | G9: =+'Income Statement'!G11 -> 0.090404276 | H9: Current public market trading. CLEAR DISCOUNT TO PEERS Opportunity multiple.
B10: PEER MEDIAN | E10: =MEDIAN(E4:E9) -> 19.605 | F10: =MEDIAN(F4:F9) -> 0.535 | G10: =MEDIAN(G4:G9) -> 0.135

Sheet WACC Calculation
B2: WACC Calculation
B4: Target Capital Structure
B5: Debt % | C5: 0.3
B6: Equity % | C6: =1-C5 -> 0.7
B8: Cost of Equity (CAPM)
B9: Risk-free rate (UK 10Y) | C9: 0.0501 | E9: UK 10y on Bloomberg on May 14th, 3pm
B10: Equity Risk Premium | C10: 0.055
B11: Beta (Rightmove, levered) | C11: 0.95
B12: Cost of Equity (Re) | C12: =C9+C11*C10 -> 0.10235
B14: Cost of Debt
B15: Pre-tax Cost of Debt | C15: 0.055
B16: Tax Rate | C16: =Assumptions!D83 -> 0.25
B17: After-tax Cost of Debt | C17: =C15*(1-C16) -> 0.04125
B19: WACC | C19: =C6*C12+C5*C17 -> 0.08402

Sheet Football Field
B2: Rightmove plc - Valuation Football Field
C4: FY+1 EBITDA (2026E) | D4: ='Income Statement'!H25 -> 325.89255
C6: Trading Comps EV/EBITDA | D6: =+G6*J6 -> 2933.0329 | E6: =+F6-D6 -> 1629.4627 | F6: =+H6*J6 -> 4562.4956 | G6: 9 | H6: 14 | I6: FY+1 EBITDA | J6: =+D4 -> 325.89255
C7: DCF (10-12% WACC, 2-3% PGR) | D7: 4500 | E7: =+F7-D7 -> 1000 | F7: 5500 | G7: WACC / PGR sensitivity
C8: LBO (5-year exit, 12x exit) | D8: 3300 | E8: =+F8-D8 -> 500 | F8: 3800 | G8: 5-yr exit, 12x exit mult, 20-25% IRR target
C9: Current Trading | D9: ='Income Statement'!H25*9 -> 2933.0329 | E9: =+F9-D9 -> 1629.4627 | F9: ='Income Statement'!H25*14 -> 4562.4956

Sheet Charts
A1: Charts (to be populated as needed)

Sheet metrics
D5: UK PROPERTY MARKET (millions) | E5: RIGHTMOVE PLC. % of MARKET
C6: Monthly Visitors | D6: 145 | E6: 0.86
C7: Properties Listed | D7: 120 | E7: 0.8
