Workbook
Name start: FinModel!#REF!
Name start: [1]FinModel!#REF!
Name tax: [2]FinModel!$D$100

Sheet FinModel
A1: Novo Nordisk
A2: All in DKK'm unless otherwise specified
G5: Historical | J5: Forecast
G6: 2021A | H6: 2022A | I6: 2023A | J6: 2024E | K6: 2025E | L6: justification: | S6: Notes:
B8: Income Statement | L8: X
C9: Revenue | G9: 140800 | H9: 176954 | I9: 232261 | J9: =J132 -> 287792.06 | K9: =K132 -> 356574.36
C10: Cost of goods sold | G10: =G157+G158 -> -19978 | H10: =H157+H158 -> -24373 | I10: =I157+I158 -> -30815 | J10: =-J9*J151 -> -38910.98 | K10: =-K9*K151 -> -47759.429 | L10: adjusted excluding depreciation, amortisation, and impairment loss
B11: Gross Profit | G11: =G9+G10 -> 120822 | H11: =H9+H10 -> 152581 | I11: =I9+I10 -> 201446 | J11: =J9+J10 -> 248881.08 | K11: =K9+K10 -> 308814.93
C12: % margin | G12: =G11/G9 -> 0.8581108 | H12: =H11/H9 -> 0.86226364 | I12: =I11/I9 -> 0.86732598 | J12: =J11/J9 -> 0.86479481 | K12: =K11/K9 -> 0.8660604
C14: Administrative expenses | G14: =-4050+G159 -> -3653 | H14: =-4467+H159 -> -4040 | I14: =-4855+I159 -> -4460 | J14: =-J9*J152 -> -4892.465 | K14: =-K9*K152 -> -6061.7642 | L14: adjusted
C15: Sales and distribution costs | G15: =-37008+G160 -> -36560 | H15: =-46217+H160 -> -45759 | I15: =-56743+I160 -> -56230 | J15: =-J9*J153 -> -60436.333 | K15: =-K9*K153 -> -74880.616 | L15: ^
C16: Research and development costs | G16: =-17772+G161 -> -16292 | H16: =-24047+H161 -> -21761 | I16: =-32443+I161 -> -29373 | J16: =-J9*J154 -> -48924.65 | K16: =-K9*K154 -> -60617.642 | L16: ^
C17: Other operating income and expenses | G17: =332-G162 -> 352 | H17: =1034-H162 -> 1150 | I17: =119-I162 -> 604 | J17: -163 | K17: -163 | L17: ^ | M17: forecasting other operating income? H1 2024
C18: Depreciation and Impairment losses on PPE | G18: -4386 | H18: -5003 | I18: -6165 | J18: =J165 -> -8315.5561 | K18: =K165 -> -10746.174
C19: Amortisation and Impairment losses on Intangible asset | G19: -1639 | H19: -2359 | I19: -3248 | J19: -5700 | K19: =K166 -> -4069.6345 | L19: Exceptional Item: Impairment loss intangible asset Ocedurenone
C21: Total Depreciation, Amortisation, and Impairment losses | G21: =SUM(G18:G19) -> -6025 | H21: =SUM(H18:H19) -> -7362 | I21: =SUM(I18:I19) -> -9413 | J21: =SUM(J18:J19) -> -14015.556 | K21: =SUM(K18:K19) -> -14815.809
B22: Operating Profit | G22: =G11+SUM(G14:G19) -> 58644 | H22: =H11+SUM(H14:H19) -> 74809 | I22: =I11+SUM(I14:I19) -> 102574 | J22: =J11+SUM(J14:J19) -> 120449.08 | K22: =K11+SUM(K14:K19) -> 152276.1
B24: EBITDA | G24: =G22-G18-G19 -> 64669 | H24: =H22-H18-H19 -> 82171 | I24: =I22-I18-I19 -> 111987 | J24: =J22-J18-J19 -> 134464.63 | K24: =K22-K18-K19 -> 167091.91
C25: % margin | G25: =G24/G9 -> 0.45929687 | H25: =H24/H9 -> 0.46436362 | I25: =I24/I9 -> 0.48216016 | J25: =J24/J9 -> 0.46722843 | K25: =K24/K9 -> 0.46860327 | L25: so loww why | M25: spends record amounts on research to fend off rivals (on what?)
C27: Financial income | G27: 2887 | H27: 239 | I27: 2945 | J27: =I27 -> 2945 | K27: =J27 -> 2945 | L27: 2022 low bc no capital gains from forward contracts, investments, marketable securities
C28: Financial costs | G28: -2451 | H28: -5986 | I28: -845 | J28: =-J238 -> -1521.5037 | K28: =-K238 -> -1347.732
B29: PBT | G29: =G22+G27+G28 -> 59080 | H29: =H22+H27+H28 -> 69062 | I29: =I22+I27+I28 -> 104674 | J29: =J22+J27+J28 -> 121872.57 | K29: =K22+K27+K28 -> 153873.37
C31: Income tax expense | G31: -11323 | H31: -13537 | I31: -20991 | J31: =-J29*J228 -> -23155.789 | K31: =-K29*K228 -> -29235.941
B32: Profit for the period | G32: =G29+G31 -> 47757 | H32: =H29+H31 -> 55525 | I32: =I29+I31 -> 83683 | J32: =SUM(J29,J31) -> 98716.784 | K32: =SUM(K29,K31) -> 124637.43
C33: % margin | G33: =G32/G9 -> 0.33918324 | H33: =H32/H9 -> 0.31378211 | I33: =I32/I9 -> 0.36029725 | J33: =J32/J9 -> 0.34301427 | K33: =K32/K9 -> 0.3495412
B36: Balance Sheet
C37: Cash at bank | G37: 10720 | H37: 12653 | I37: 14392 | J37: =J125+327 -> 15881.674 | K37: =K125-6420 -> 16044.683
C38: Trade receivables | G38: 40643 | H38: 50560 | I38: 64770 | J38: =J9/J173 -> 81230.462 | K38: =K9/K173 -> 100037.09
C39: Tax receivables | G39: 1119 | H39: 940 | I39: 2423 | J39: =J9/J174 -> 2025.9504 | K39: =K9/K174 -> 2997.5611
C40: Other receivables and prepayments | G40: 5037 | H40: 6005 | I40: 8068 | J40: =J9/J175 -> 9880.3049 | K40: =K9/K175 -> 12313.548
C41: Inventory | G41: 19621 | H41: 24388 | I41: 31811 | J41: =-J10/J176 -> 39542.171 | K41: =-K10/K176 -> 48915.608
C42: Marketable securities | G42: 6765 | H42: 10921 | I42: 15838 | J42: =I42 -> 15838 | K42: =J42 -> 15838
C43: Derivative financial instruments | G43: 1690 | H43: 2727 | I43: 2344 | J43: =I43 -> 2344 | K43: =J43 -> 2344
B44: Total Current Assets | G44: =SUM(G37:G43) -> 85595 | H44: =SUM(H37:H43) -> 108194 | I44: =SUM(I37:I43) -> 139646 | J44: =SUM(J37:J43) -> 166742.56 | K44: =SUM(K37:K43) -> 198490.49
C46: Property, plant and equipment | G46: 55362 | H46: 66671 | I46: 90961 | J46: =J203 -> 116877.44 | K46: =K203 -> 155253.27 | L46: significant step up in CAPEX
C47: Intangible assets | G47: 43171 | H47: 51416 | I47: 60406 | J47: =J209 -> 69085.659 | K47: =K209 -> 77254.024
C48: Investments in associated companies | G48: 525 | H48: 327 | I48: 410 | J48: =I48 -> 410 | K48: =J48 -> 410
C49: Deferred income tax assets | G49: 8672 | H49: 13427 | I49: 20380 | J49: =I49 -> 20380 | K49: =J49 -> 20380
C50: Other receivables and prepayments | G50: 267 | H50: 206 | I50: 1430 | J50: =I50 -> 1430 | K50: =J50 -> 1430
C51: Other financial assets | G51: 916 | H51: 1016 | I51: 1253 | J51: 1521 | K51: =J51 -> 1521
...

Sheet Valuation 10y
A1: Novo Nordisk
A6: FCFE method | D6: 0 | E6: 1 | F6: 2 | G6: 3 | H6: 4 | I6: 5 | J6: 6 | K6: 7 | L6: 8 | M6: 9 | N6: 10 | P6: Risk-free rate (DK10-Year Govt Bond Yield) | Q6: 0.02206
B7: In DKK mil | D7: 2023 | E7: 2024 | F7: 2025 | G7: 2026 | H7: 2027 | I7: 2028 | J7: 2029 | K7: 2030 | L7: 2031 | M7: 2032 | N7: 2033 | P7: Beta (vs. OMXC25) | Q7: 0.88
B8: CFO | D8: =FinModel!I104 -> 108908 | E8: =FinModel!J104 -> 133099.7 | F8: =FinModel!K104 -> 168033.5 | G8: =F8*(1+Q11) -> 171058.1 | H8: =G8*(1+Q11) -> 174137.15 | I8: =H8*(1+$Q$11) -> 177271.62 | J8: =I8*(1+$Q$11) -> 180462.51 | K8: =J8*(1+$Q$11) -> 183710.83 | L8: =K8*(1+$Q$11) -> 187017.63 | M8: =L8*(1+$Q$11) -> 190383.95 | N8: =M8*(1+$Q$11) -> 193810.86 | P8: Market return (Rm) | Q8: 0.0457
B9: (CAPEX) | D9: =FinModel!I107+FinModel!I106 -> -38896 | E9: =FinModel!J107+FinModel!J106 -> -46470 | F9: =FinModel!K107+FinModel!K106 -> -61360 | G9: =F9 -> -61360 | H9: =G9 -> -61360 | I9: =H9 -> -61360 | J9: =I9 -> -61360 | K9: =J9 -> -61360 | L9: =K9 -> -61360 | M9: =L9 -> -61360 | N9: =M9 -> -61360 | P9: Cost of Equity | Q9: =Q6+(Q7*(Q8-Q6)) -> 0.0428632
B10: FCFE | D10: =D8+D9 -> 70012 | E10: =E8+E9 -> 86629.698 | F10: =F8+F9 -> 106673.5 | G10: =G8+G9 -> 109698.1 | H10: =H8+H9 -> 112777.15 | I10: =I8+I9 -> 115911.62 | J10: =J8+J9 -> 119102.51 | K10: =K8+K9 -> 122350.83 | ... N10: =N8+N9 -> 132450.86
B11: Discount factor | D11: =1/(1+$T$41)^D6 -> 1 | E11: =1/(1+$T$41)^E6 -> 0.959007 | F11: =1/(1+$T$41)^F6 -> 0.91969442 | G11: =1/(1+$T$41)^G6 -> 0.88199338 | H11: =1/(1+$T$41)^H6 -> 0.84583782 | I11: =1/(1+$T$41)^I6 -> 0.81116439 | J11: =1/(1+$T$41)^J6 -> 0.77791232 | K11: =1/(1+$T$41)^K6 -> 0.74602336 | ... N11: =1/(1+$T$41)^N6 -> 0.65798767 | P11: LT growth (inflation % yoy) | Q11: 0.018
B12: PV | D12: =D11*D10 -> 70012 | E12: =E11*E10 -> 83078.486 | F12: =F11*F10 -> 98107.023 | G12: =G11*G10 -> 96753.002 | H12: =H11*H10 -> 95391.179 | I12: =I11*I10 -> 94023.377 | J12: =J11*J10 -> 92651.308 | K12: =K11*K10 -> 91276.579 | ... N12: =N11*N10 -> 87151.03
P14: Total Debt | Q14: =FinModel!I56+FinModel!I64 -> 27006
P15: Market Value of Debt
B16: Sum of PV | D16: =SUM(D12:N12) -> 986869.75 | P16: Cost of debt | Q16: =FinModel!I238/'Valuation 10y'!Q14 -> 0.031289343
B17: Terminal value | D17: =(N10*(1+Q11))/(Q9-Q11) -> 5423073.9
B18: PV of terminal value | D18: =D17/(1+Q9)^10 -> 3564282.3 | P18: Tax rate | Q18: =-FinModel!I228 -> 0.20053691
B19: Equity Value (DKK mil) | D19: =D18+D16 -> 4551152.1
B21: Target Price: | D21: =D19/4465 -> 1019.295
B22: Upside: | D22: =D21/912-1 -> 0.11764801
P23: WACC = % of equity x cost of equity + % of debt x cost of debt x (1 - Tax Rate)
P24: Cost of equity = Risk free rate + Beta x Market Risk Premium
B25: Calculating Equity IRR
B26: In DKK mil | D26: 2019 | E26: 2020 | F26: 2021 | G26: 2022 | H26: 2023 | I26: 2024 | J26: 2025 | K26: Terminal Value | P26: WACC
B27: Outlay | D27: =-D35 -> -4045608 | P27: Market Cap (DKK) | T27: 4060000000000 | U27: 4060000 | V27: million
B28: FCFE | E28: =D10 -> 70012 | F28: =E10 -> 86629.698 | G28: =F10 -> 106673.5 | H28: =G10 -> 109698.1 | I28: =H10 -> 112777.15 | J28: =I10 -> 115911.62 | K28: =D17 -> 5423073.9 | P28: % of Equity | T28: =T27/(T27+T34) -> 0.99339223
P29: Cost of Equity | T29: =T30+T31*T32 -> 0.0428632
P30: Risk Free Rate | T30: =Q6 -> 0.02206
B31: Proposed EV/EBITDA (X) | P31: Beta | T31: =Q7 -> 0.88
B32: 2018 EBITDA | P32: Market Risk Premium | T32: =Q8-Q6 -> 0.02364
B33: Enterprise Value | D33: =U27+Q14-FinModel!I37 -> 4072614 | E33: EV= market cap + debt - cash
B34: Less: Debt | D34: =-Q14 -> -27006 | P34: Debt | T34: 27006000000
B35: Equity Value (DKK mil) | D35: =D33+D34 -> 4045608 | P35: % of Debt | T35: =T34/(T27+T34) -> 0.0066077711
P36: Cost of Debt | T36: =Q16 -> 0.031289343
B37: Equity IRR | D37: =IRR(D27:K28) -> 0.061843826 | P37: Tax Rate | T37: =Q18 -> 0.20053691
G39: 5 years: | H39: 545982.68 | P39: Total | T39: =T27+T34 -> 4087006000000
B40: Multiple Method | G40: tv | H40: 4442012
G41: pv | H41: 3595355.4 | P41: WACC | T41: =T28*T29+(T35*T36*(1-T37)) -> 0.042745261
B42: Companies with most similair EBITDA margin to WidgePro | G42: equity value | H42: =H39+H41 -> 4141338.1
B43: Comp | C43: 2021 PE Multiple | D43: 2021 EV EBITDA multiple | E43: ebitda margin | H43: =H42/4465 -> 927.51134
B44: A | C44: 14.56 | D44: 9.95 | E44: 0.29874316 | H44: =H43/912-1 -> 0.017008043
B45: C | C45: 11.864 | D45: 9.679 | E45: 0.31191272
B46: E | C46: 8.078 | D46: 4.002 | E46: 0.31336712
B47: G | C47: 11.766 | D47: 5.931 | E47: 0.2851746
...

Sheet Ratio
A1: Financial Data | B1: 2021 | C1: 2022 | D1: 2023 | E1: 2024 | F1: 2025 | G1: 2026
A2: Revenue (Million Euros) | E2: 37959 | F2: 40152 | G2: 42492
A3: Revenue Growth | E3: 0.0573 | F3: 0.0578 | G3: 0.0583
A4: EBITDA (Million Euros) | E4: 7848 | F4: 8337 | G4: 8837
A5: EBIT (Million Euros) | E5: 6415 | F5: 6937 | G5: 7466
A6: PBT (Million Euros) | E6: 5950 | F6: 6505 | G6: 7063
A7: PATAMI (Million Euros) | E7: 3915 | F7: 4341 | G7: 4769
A8: EPS | E8: 8.25 | F8: 9.02 | G8: 9.78
A9: BVPS | E9: 52.64 | F9: 57.13 | G9: 62
A10: GDPS | E10: 4.14 | F10: 4.53 | G10: 4.91
A11: CFO | E11: 6330 | F11: 6082 | G11: 6458
A12: FCF | E12: 5132 | F12: 4884 | G12: 5260
A13: Key Ratios | B13: 2021 | C13: 2022 | D13: 2023 | E13: 2024 | F13: 2025 | G13: 2026
A14: PER (x) | E14: 27.49 | F14: 25.17 | G14: 23.2
A15: PTBV (x) | E15: 4.31 | F15: 3.97 | G15: 3.66
A16: Div. yield (%) | E16: 0.0183 | F16: 0.0199 | G16: 0.0216
A17: Div. payout (%) | E17: 0.502 | F17: 0.502 | G17: 0.502
A18: EBITDA margin (%) | E18: 0.2067 | F18: 0.2076 | G18: 0.208
A19: EBIT margin (%) | E19: 0.169 | F19: 0.1728 | G19: 0.1757
A20: PBT margin (%) | E20: 0.1568 | F20: 0.162 | G20: 0.1662
A21: PATAMI margin (%) | E21: 0.1031 | F21: 0.1081 | G21: 0.1122
A22: ROE (%) | E22: 0.1568 | F22: 0.1578 | G22: 0.1577
A23: ROA (%) | E23: 0.0763 | F23: 0.0806 | G23: 0.0843
A24: Net debt (Million Euros) | E24: 6466 | F24: 4115 | G24: 1604
A25: Net gearing (x) | E25: 0.43 | F25: 0.37 | G25: 0.31
A26: FCF yield (%) | E26: 0.0404 | F26: 0.0384 | G26: 0.0414
A28: Total Number of shares | E28: 3.4 billion
A29: Average Share Price | B29: 226.9 | C29: 226.9 | D29: 226.9 | E29: 226.9 | F29: 226.9 | G29: 226.9
A31: historical, key financial highlights, forward looking too
A33: current outstanding shares: 4465 million as of June 2024

Sheet CCA
B3: sales by segment | G3: sales by region | I3: Mainland China, Hong Kong and Taiwan | J3: Rest of World: All other countries except for North America.
B4: Diabetes and Obesity Care | C4: 0.93 | G4: EMEA | H4: North America Operations | I4: China | J4: Rest of the world
B5: Rare Disease | C5: 0.07 | G5: 50867 | H5: 136629 | I5: 16687 | J5: 28078 | K5: =G5+H5+I5+J5 -> 232261
G6: =G5/$K$5*100 -> 21.900793 | H6: =H5/$K$5*100 -> 58.825632 | I6: =I5/$K$5*100 -> 7.1845898 | J6: =J5/$K$5*100 -> 12.088986
B7: 0.93 | C7: 0.07
B8: 215098 | C8: 17163 | D8: =B8+C8 -> 232261 | G8: =FinModel!K104 -> 168033.5 | H8: =G8*(1+O14) -> 168033.5
F11: =1/(1+$O$12)^F6 -> 1
E16: =SUM(E12:K12) -> 0
E17: =(K10*(1+O14))/(O12-O14) -> #DIV/0!
E18: =E17/(1+O12)^6 -> #DIV/0!
E19: =E18+E16 -> #DIV/0!
B25: earnings per share ratio | I25: P/E ratio comparison with competitors | K25: source: yahoo finance
B26: year | C26: 2019 | D26: 2020 | E26: 2021 | F26: 2022 | G26: 2023 | I26: companies | J26: AstraZeneca | K26: Sanofi | L26: Novo Nordisk | M26: Eli Lilly
B27: earnings per share | C27: 8.19 | D27: 9.01 | E27: 10.37 | F27: 12.22 | G27: 18.62 | I27: P/E ratio | J27: 39.19 | K27: 21.46 | L27: 46.37 | M27: 85.2
B28: % change | D28: =(D27-C27)/C27 -> 0.1001221 | E28: =(E27-D27)/D27 -> 0.1509434 | F28: =(F27-E27)/E27 -> 0.17839923 | G28: =(G27-F27)/F27 -> 0.52373159
C30: 2018
C31: 18.05
F45: why did EPS steeply increased from 2022 to 2023 | J45: why does P/E ratio differ so much?
F46: increase demand for ozempic, supply unable to keep up so causes limited supply.
B48: sales growth (DKK million) | J48: bigger company generally means bigger PE
B49: year | C49: 2019 | D49: 2020 | E49: 2021 | F49: 2022 | G49: 2023 | H49: what caused this sales growth?
B50: sales | C50: 122021 | D50: 126946 | E50: 140800 | F50: 176954 | G50: 232261 | H50: from 2022 to 2023???
B51: % change | C51: 0.091 | D51: =D53/100 -> 0.040361905 | E51: =E53/100 -> 0.10913302 | F51: =F53/100 -> 0.25677557 | G51: =G53/100 -> 0.31255015
D53: =((D50-C50)/C50)*100 -> 4.0361905 | E53: =((E50-D50)/D50)*100 -> 10.913302 | F53: =((F50-E50)/E50)*100 -> 25.677557 | G53: =((G50-F50)/F50)*100 -> 31.255015
C54: 0.091 | D54: 0.04 | E54: 0.109 | F54: 0.257 | G54: 0.313
C55: 2018
J57: diabetes drug market
J58: year | K58: 2023 | L58: 2032
J59: market value | K59: 66b | L59: 118b
B74: sales by business segment
H76: Column1 | I76: Column2 | J76: Column3

Sheet Valuation
A1: Novo Nordisk
N5: Discount Rate (cost of equity) Calculation
B6: FCFE method | E6: 0 | F6: 1 | G6: 2 | H6: 3 | I6: 4 | J6: 5
C7: In DKK mil | E7: 2023 | F7: 2024 | G7: 2025 | H7: 2026 | I7: 2027 | J7: 2028
C8: CFO | E8: =FinModel!I104 -> 108908 | F8: =FinModel!J104 -> 133099.7 | G8: =FinModel!K104 -> 168033.5 | H8: =G8*(1+O14) -> 171058.1 | I8: =H8*(1+O14) -> 174137.15 | J8: =I8*(1+$O$14) -> 177271.62
C9: (CAPEX) | E9: =FinModel!I107+FinModel!I106 -> -38896 | F9: =FinModel!J107+FinModel!J106 -> -46470 | G9: =FinModel!K107+FinModel!K106 -> -61360 | H9: =G9 -> -61360 | I9: =H9 -> -61360 | J9: =I9 -> -61360 | N9: Risk-free rate (DK10-Year Govt Bond Yield) | O9: 0.02206
C10: FCFE | E10: =E8+E9 -> 70012 | F10: =F8+F9 -> 86629.698 | G10: =G8+G9 -> 106673.5 | H10: =H8+H9 -> 109698.1 | I10: =I8+I9 -> 112777.15 | J10: =J8+J9 -> 115911.62 | N10: Beta (vs. OMXC25) | O10: 0.88
C11: Discount factor | E11: =1/(1+$O$12)^E6 -> 1 | F11: =1/(1+$O$12)^F6 -> 0.95889854 | G11: =1/(1+$O$12)^G6 -> 0.91948641 | H11: =1/(1+$O$12)^H6 -> 0.88169418 | I11: =1/(1+$O$12)^I6 -> 0.84545526 | J11: =1/(1+$O$12)^J6 -> 0.81070581 | N11: Market return (Rm) | O11: 0.0457
C12: PV | E12: =E11*E10 -> 70012 | F12: =F11*F10 -> 83069.091 | G12: =G11*G10 -> 98084.834 | H12: =H11*H10 -> 96720.179 | I12: =I11*I10 -> 95348.034 | J12: =J11*J10 -> 93970.223 | N12: Cost of Equity | O12: =O9+(O10*(O11-O9)) -> 0.0428632
N14: LT growth (inflation % yoy) | O14: 0.018
C16: Sum of PV | E16: =SUM(E12:J12) -> 537204.36
C17: Terminal value | E17: =(J10*(1+O14))/(O12-O14) -> 4745890.6 | N17: Total Debt | O17: =FinModel!I56+FinModel!I64 -> 27006
C18: PV of terminal value | E18: =E17/(1+O12)^5 -> 3847521.1 | N18: Market Value of Debt
C19: Equity Value (DKK mil) | E19: =E18+E16 -> 4384725.5 | N19: Cost of debt | O19: =FinModel!I238/Valuation!O17 -> 0.031289343
C21: Target Price: | E21: =E19/4465 -> 982.02138 | N21: Tax rate | O21: =-FinModel!I228 -> 0.20053691
C22: Upside: | E22: =E21/912-1 -> 0.076777833
N23: WACC
C25: Calculating Equity IRR
C26: In DKK mil | E26: 2019 | F26: 2020 | G26: 2021 | H26: 2022 | I26: 2023 | J26: 2024 | K26: 2025 | L26: Terminal Value
C27: Outlay | E27: =-E35 -> -77.731
C28: FCFE | F28: =E10 -> 70012 | G28: =F10 -> 86629.698 | H28: =G10 -> 106673.5 | I28: =H10 -> 109698.1 | J28: =I10 -> 112777.15 | K28: =J10 -> 115911.62 | L28: =E17 -> 4745890.6
C30: Seller's propossal
C31: Proposed EV/EBITDA (X) | E31: 13
C32: 2018 EBITDA | E32: =[3]FinModel!H21 -> 6.51
C33: Enterprise Value | E33: =E31*E32 -> 84.63
C34: Less: Debt | E34: =-[3]FinModel!H49 -> -6.899
C35: Equity Value (USD mil) | E35: =E33+E34 -> 77.731
C37: Equity IRR | E37: =IRR(E27:L28) -> 900.93334
H39: 5 years: | I39: 545982.68
C40: Multiple Method | H40: tv | I40: 4442012
H41: pv | I41: 3595355.4
C42: Companies with most similair EBITDA margin to WidgePro | H42: equity value | I42: =I39+I41 -> 4141338.1
C43: Comp | D43: 2021 PE Multiple | E43: 2021 EV EBITDA multiple | F43: ebitda margin | I43: =I42/4465 -> 927.51134
C44: A | D44: 14.56 | E44: 9.95 | F44: 0.29874316 | I44: =I43/912-1 -> 0.017008043
C45: C | D45: 11.864 | E45: 9.679 | F45: 0.31191272
C46: E | D46: 8.078 | E46: 4.002 | F46: 0.31336712
C47: G | D47: 11.766 | E47: 5.931 | F47: 0.2851746
C48: L | D48: 14.259 | E48: 10.425 | F48: 0.31532794
C49: D | D49: 14.426 | E49: 8.965 | F49: 0.24619148
C50: Average | D50: =AVERAGE(D44:D49) -> 12.492167 | E50: =AVERAGE(E44:E49) -> 8.1586667 | F50: =AVERAGE(F44:F49) -> 0.2951195
...
